Workbook
Name _GoBack: 'I1'!$C$50
Name _GoBack: 'I2'!$C$50
Name OLE_LINK1: 'IAT-1'!$A$14
Name OLE_LINK5: 'I1'!$B$15
Name OLE_LINK5: 'I2'!$B$15

Sheet BL-1
A1: JAYARAJ ANNAPACKIAM C. S. I. COLLEGE OF ENGINEERING | M1: FORM NO.: F02
A2: (Approved by AICTE, New Delhi and Affiliated to Anna University)
A3: MARGOSCHIS NAGAR, NAZARETH - 628 617
A4: DEPARTMENT OF ARTIFICIAL INTELLIGENCE AND DATA SCIENCE
A5: QUESTION PAPER CO / BT MAPPING
A6: CONTINUOUS ASSESSMENT TEST - I
A8: COURSE CODE / NAME: CW3551 DATA AND INFORMATION SECURITY | I8: BATCH: 2023-2027 | M8: SEM:05
A9: COURSE INSTRUCTOR/DESIGNATION: G. ALISHA EVANGELINE,AP/ADS | I9: CLASS : III ADS | M9: DATE: | N9: 20/09/2025 | O9: TIME: | P9: 11:30-1.00
A11: COURSE OUTCOMES:
A12: CO 1 | B12: Understand the basics of data and information security
A13: CO 2 | B13: Understand the legal, ethical and professional issues in information security
A14: CO 3 | B14: Understand the various authentication schemes to simulate different applications
A15: CO 4 | B15: Understand various security practices and system security standards
A16: CO 5 | B16: Understand the web security protocols for E-commerce applications
B18: CO SEM / SUB / .NO | C18: PART - A (5 X 2 = 10) | H18: PART - B (4 X 10 = 40) | M18: TOTAL MARKS (50) | N18: TOTAL %
C19: 1 | D19: 2 | E19: 3 | F19: 4 | G19: 5 | H19: 6 | I19: 7 | J19: 8 | K19: 9 | L19: 10
A20: COURSE OUTCOMES | B20: =A12 -> CO 1 | C20: ü | D20: ü | H20: ü | L20: ü | M20: =COUNTIF(C20:G20,"*")*2+COUNTIF(H20:K20,"*")*7+COUNTIF(L20,"*")*12 -> 23 | N20: =ROUND(M20/50*100,1) -> 46
B21: =A13 -> CO 2 | E21: ü | F21: ü | I21: ü | J21: ü | M21: =COUNTIF(C21:G21,"*")*2+COUNTIF(H21:K21,"*")*7+COUNTIF(L21,"*")*12 -> 18 | N21: =ROUND(M21/50*100,1) -> 36
B22: =A14 -> CO 3 | G22: ü | K22: ü | M22: =COUNTIF(C22:G22,"*")*2+COUNTIF(H22:K22,"*")*7+COUNTIF(L22,"*")*12 -> 9 | N22: =ROUND(M22/50*100,1) -> 18
B23: =A15 -> CO 4 | M23: =COUNTIF(C23:G23,"*")*2+COUNTIF(H23:K23,"*")*7+COUNTIF(L23,"*")*12 -> 0 | N23: =ROUND(M23/50*100,1) -> 0
B24: =A16 -> CO 5 | M24: =COUNTIF(C24:G24,"*")*2+COUNTIF(H24:K24,"*")*7+COUNTIF(L24,"*")*12 -> 0 | N24: =ROUND(M24/50*100,1) -> 0
A25: BLOOM'S TAXONOMY | B25: REMEMBER | E25: ü | M25: =COUNTIF(C25:G25,"*")*2+COUNTIF(H25:K25,"*")*7+COUNTIF(L25,"*")*12 -> 2 | N25: =ROUND(M25/50*100,1) -> 4
B26: UNDERSTAND | C26: ü | D26: ü | F26: ü | G26: ü | H26: ü | I26: ü | J26: ü | K26: ü | L26: ü | M26: =COUNTIF(C26:G26,"*")*2+COUNTIF(H26:K26,"*")*7+COUNTIF(L26,"*")*12 -> 48 | N26: =ROUND(M26/50*100,1) -> 96
B27: APPLY | M27: =COUNTIF(C27:G27,"*")*2+COUNTIF(H27:K27,"*")*7+COUNTIF(L27,"*")*12 -> 0 | N27: =ROUND(M27/50*100,1) -> 0
B28: ANALYZE | J28: ü | M28: =COUNTIF(C28:G28,"*")*2+COUNTIF(H28:K28,"*")*7+COUNTIF(L28,"*")*12 -> 7 | N28: =ROUND(M28/50*100,1) -> 14
B29: EVALUATE | M29: =COUNTIF(C29:G29,"*")*2+COUNTIF(H29:K29,"*")*7+COUNTIF(L29,"*")*12 -> 0 | N29: =ROUND(M29/50*100,1) -> 0
B30: CREATE | H30: ü | L30: ü | M30: =COUNTIF(C30:G30,"*")*2+COUNTIF(H30:K30,"*")*7+COUNTIF(L30,"*")*12 -> 19 | N30: =ROUND(M30/50*100,1) -> 38
A31: DATE OF EXAM | M31: 20/09/2025
A32: COURSE INCHARGE
A33: HOD
A34: PRINCIPAL
B39: Blooms Level | C39: key words
B40: REMEMBER | C40: Define, List, Statementn, Find, Locate.
B41: UNDERSTAND | C41: What, How, Classify, Describe, Discuss, Explain, Identify, Select, Outline.
B42: APPLY | C42: Execute, Implement, Solve, Use, Interpret, Demonstrate, Sketch, Illustrate, Complete, Draw, Apply, Calculate.
B43: ANALYZE | C43: Differentiate, Compare, Contrast, Distinguish, Examine, Test, Organize, Identify, Categorize.
B44: EVALUATE | C44: Justify, Judge, Appraise, Defend, Argue, Valuate, Prioritize, Criticize.
B45: CREATE | C45: Construct, Design, Assemble, Format, Investigate, Develop, Formulate, Create, Imagine, Produce, Invent, Plan, Build.

Sheet BL-2
A1: ='BL-1'!A1:L1 -> JAYARAJ ANNAPACKIAM C. S. I. COLLEGE OF ENGINEERING | M1: FORM NO.: F02
A2: ='BL-1'!A2:L2 -> (Approved by AICTE, New Delhi and Affiliated to Anna University)
A3: ='BL-1'!A3:L3 -> MARGOSCHIS NAGAR, NAZARETH - 628 617
A4: ='BL-1'!A4:L4 -> DEPARTMENT OF ARTIFICIAL INTELLIGENCE AND DATA SCIENCE
A5: ='BL-1'!A5:L5 -> QUESTION PAPER CO / BT MAPPING
A6: CONTINUOUS ASSESSMENT TEST - II
A8: ='BL-1'!A8:H8 -> COURSE CODE / NAME: CW3551 DATA AND INFORMATION SECURITY | I8: ='BL-1'!I8 -> BATCH: 2023-2027 | M8: ='BL-1'!M8 -> SEM:05
A9: ='BL-1'!A9:H9 -> COURSE INSTRUCTOR/DESIGNATION: G. ALISHA EVANGELINE,AP/ADS | I9: ='BL-1'!I9 -> CLASS : III ADS | M9: ='BL-1'!M9 -> DATE: | N9: 45758 | O9: ='BL-1'!O9 -> TIME: | P9: 11:15-12:45
A11: COURSE OUTCOMES:
A12: ='BL-1'!A12 -> CO 1 | B12: ='BL-1'!B12 -> Understand the basics of data and information security
A13: ='BL-1'!A13 -> CO 2 | B13: ='BL-1'!B13 -> Understand the legal, ethical and professional issues in information security
A14: ='BL-1'!A14 -> CO 3 | B14: ='BL-1'!B14 -> Understand the various authentication schemes to simulate different applications
A15: ='BL-1'!A15 -> CO 4 | B15: ='BL-1'!B15 -> Understand various security practices and system security standards
A16: ='BL-1'!A16 -> CO 5 | B16: ='BL-1'!B16 -> Understand the web security protocols for E-commerce applications
B18: CO SEM / SUB / . NO. | C18: PART - A (5 X 2 = 10) | H18: PART - B (4 X 10 = 40) | M18: TOTAL MARKS (50) | N18: TOTAL %
C19: 1 | D19: 2 | E19: 3 | F19: 4 | G19: 5 | H19: 6 | I19: 7 | J19: 8 | K19: 9 | L19: 10
A20: COURSE OUTCOMES | B20: =A12 -> CO 1 | M20: =COUNTIF(C20:G20,"*")*2+COUNTIF(H20:K20,"*")*7+COUNTIF(L20,)*12 -> 0 | N20: =ROUND(M20/50*100,1) -> 0
B21: =A13 -> CO 2 | M21: =COUNTIF(C21:G21,"*")*2+COUNTIF(H21:K21,"*")*7+COUNTIF(L21,)*12 -> 0 | N21: =ROUND(M21/50*100,1) -> 0
B22: =A14 -> CO 3 | C22: ü | H22: ü | M22: =COUNTIF(C22:G22,"*")*2+COUNTIF(H22:K22,"*")*7+COUNTIF(L22,"*")*12 -> 9 | N22: =ROUND(M22/50*100,1) -> 18
B23: =A15 -> CO 4 | D23: ü | E23: ü | I23: ü | J23: ü | M23: =COUNTIF(C23:G23,"*")*2+COUNTIF(H23:K23,"*")*7+COUNTIF(L23,"*")*12 -> 18 | N23: =ROUND(M23/50*100,1) -> 36
B24: =A16 -> CO 5 | F24: ü | G24: ü | K24: ü | L24: ü | M24: =COUNTIF(C24:G24,"*")*2+COUNTIF(H24:K24,"*")*7+COUNTIF(L24,"*")*12 -> 23 | N24: =ROUND(M24/50*100,1) -> 46
A25: BLOOM'S TAXONOMY | B25: REMEMBER | E25: ü | M25: =COUNTIF(C25:G25,"*")*2+COUNTIF(H25:K25,"*")*7+COUNTIF(L25,"*")*12 -> 2 | N25: =ROUND(M25/50*100,1) -> 4
B26: UNDERSTAND | C26: ü | F26: ü | G26: ü | H26: ü | I26: ü | K26: ü | M26: =COUNTIF(C26:G26,"*")*2+COUNTIF(H26:K26,"*")*7+COUNTIF(L26,"*")*12 -> 27 | N26: =ROUND(M26/50*100,1) -> 54
B27: APPLY | M27: =COUNTIF(C27:G27,"*")*2+COUNTIF(H27:K27,"*")*7+COUNTIF(L27,"*")*12 -> 0 | N27: =ROUND(M27/50*100,1) -> 0
B28: ANALYZE | D28: ü | J28: ü | M28: =COUNTIF(C28:G28,"*")*2+COUNTIF(H28:K28,"*")*7+COUNTIF(L28,"*")*12 -> 9 | N28: =ROUND(M28/50*100,1) -> 18
B29: EVALUATE | M29: =COUNTIF(C29:G29,"*")*2+COUNTIF(H29:K29,"*")*7+COUNTIF(L29,"*")*12 -> 0 | N29: =ROUND(M29/50*100,1) -> 0
B30: CREATE | L30: ü | M30: =COUNTIF(C30:G30,"*")*2+COUNTIF(H30:K30,"*")*7+COUNTIF(L30,"*")*12 -> 12 | N30: =ROUND(M30/50*100,1) -> 24
A31: DATE OF EXAM | M31: 45758
A32: COURSE INCHARGE
A33: HOD
A34: PRINCIPAL
B43: Blooms Level | C43: key words
B44: REMEMBER | C44: Define, List, Statementn, Find, Locate.
B45: UNDERSTAND | C45: What, How, Classify, Describe, Discuss, Explain, Identify, Select, Outline.
B46: APPLY | C46: Execute, Implement, Solve, Use, Interpret, Demonstrate, Sketch, Illustrate, Complete, Draw, Apply, Calculate.
B47: ANALYZE | C47: Differentiate, Compare, Contrast, Distinguish, Examine, Test, Organize, Identify, Categorize.
B48: EVALUATE | C48: Justify, Judge, Appraise, Defend, Argue, Valuate, Prioritize, Criticize.
B49: CREATE | C49: Construct, Design, Assemble, Format, Investigate, Develop, Formulate, Create, Imagine, Produce, Invent, Plan, Build.

Sheet BL-3
A1: ='BL-1'!A1:L1 -> JAYARAJ ANNAPACKIAM C. S. I. COLLEGE OF ENGINEERING | M1: FORM NO.: F02
A2: ='BL-1'!A2:L2 -> (Approved by AICTE, New Delhi and Affiliated to Anna University)
A3: ='BL-1'!A3:L3 -> MARGOSCHIS NAGAR, NAZARETH - 628 617
A4: ='BL-1'!A4:L4 -> DEPARTMENT OF ARTIFICIAL INTELLIGENCE AND DATA SCIENCE
A5: ='BL-1'!A5:L5 -> QUESTION PAPER CO / BT MAPPING
A6: INTERNAL ASSESSMENT TEST - III
A8: ='BL-1'!A8:H8 -> COURSE CODE / NAME: CW3551 DATA AND INFORMATION SECURITY | I8: ='BL-1'!I8 -> BATCH: 2023-2027 | M8: ='BL-1'!M8 -> SEM:05
A9: ='BL-1'!A9:H9 -> COURSE INSTRUCTOR/DESIGNATION: G. ALISHA EVANGELINE,AP/ADS | I9: ='BL-1'!I9 -> CLASS : III ADS | M9: DATE: | O9: TIME: | P9: ='BL-1'!P9 -> 11:30-1.00
A11: COURSE OUTCOMES:
A12: ='BL-1'!A12 -> CO 1 | B12: ='BL-1'!B12 -> Understand the basics of data and information security
A13: ='BL-1'!A13 -> CO 2 | B13: ='BL-1'!B13 -> Understand the legal, ethical and professional issues in information security
A14: ='BL-1'!A14 -> CO 3 | B14: ='BL-1'!B14 -> Understand the various authentication schemes to simulate different applications
A15: ='BL-1'!A15 -> CO 4 | B15: ='BL-1'!B15 -> Understand various security practices and system security standards
A16: ='BL-1'!A16 -> CO 5 | B16: ='BL-1'!B16 -> Understand the web security protocols for E-commerce applications
B18: CO SEM / SUB / .NO | C18: PART - A (5 X 2 = 10) | H18: PART - B (4 X 10 = 40) | M18: TOTAL MARKS (50) | N18: TOTAL %
C19: 1 | D19: 2 | E19: 3 | F19: 4 | G19: 5 | H19: 6 | I19: 7 | J19: 8 | K19: 9 | L19: 10
A20: COURSE OUTCOMES | B20: =A12 -> CO 1 | M20: =COUNTIF(C20:G20,"*")*2+COUNTIF(H20:L20,"*")*8 -> 0 | N20: =ROUND(M20/50*100,1) -> 0
B21: =A13 -> CO 2 | M21: =COUNTIF(C21:G21,"*")*2+COUNTIF(H21:L21,"*")*8 -> 0 | N21: =ROUND(M21/50*100,1) -> 0
B22: =A14 -> CO 3 | M22: =COUNTIF(C22:G22,"*")*2+COUNTIF(H22:L22,"*")*8 -> 0 | N22: =ROUND(M22/50*100,1) -> 0
B23: =A15 -> CO 4 | M23: =COUNTIF(C23:G23,"*")*2+COUNTIF(H23:L23,"*")*8 -> 0 | N23: =ROUND(M23/50*100,1) -> 0
B24: =A16 -> CO 5 | M24: =COUNTIF(C24:G24,"*")*2+COUNTIF(H24:L24,"*")*8 -> 0 | N24: =ROUND(M24/50*100,1) -> 0
A25: BLOOM'S TAXONOMY | B25: REMEMBER | M25: =COUNTIF(C25:G25,"*")*2+COUNTIF(H25:L25,"*")*8 -> 0 | N25: =ROUND(M25/50*100,1) -> 0
B26: UNDERSTAND | M26: =COUNTIF(C26:G26,"*")*2+COUNTIF(H26:L26,"*")*8 -> 0 | N26: =ROUND(M26/50*100,1) -> 0
B27: APPLY | M27: =COUNTIF(C27:G27,"*")*2+COUNTIF(H27:L27,"*")*8 -> 0 | N27: =ROUND(M27/50*100,1) -> 0
B28: ANALYZE | M28: =COUNTIF(C28:G28,"*")*2+COUNTIF(H28:L28,"*")*8 -> 0 | N28: =ROUND(M28/50*100,1) -> 0
B29: EVALUATE | M29: =COUNTIF(C29:G29,"*")*2+COUNTIF(H29:L29,"*")*8 -> 0 | N29: =ROUND(M29/50*100,1) -> 0
B30: CREATE | M30: =COUNTIF(C30:G30,"*")*2+COUNTIF(H30:L30,"*")*8 -> 0 | N30: =ROUND(M30/50*100,1) -> 0
A31: DATE OF EXAM | M31: 45246
A32: COURSE INCHARGE
A33: HOD
A34: PRINCIPAL
B62: Blooms Level | C62: key words
B63: REMEMBER | C63: Define, List, Statementn, Find, Locate.
B64: UNDERSTAND | C64: What, How, Classify, Describe, Discuss, Explain, Identify, Select, Outline.
B65: APPLY | C65: Execute, Implement, Solve, Use, Interpret, Demonstrate, Sketch, Illustrate, Complete, Draw, Apply, Calculate.
B66: ANALYZE | C66: Differentiate, Compare, Contrast, Distinguish, Examine, Test, Organize, Identify, Categorize.
B67: EVALUATE | C67: Justify, Judge, Appraise, Defend, Argue, Valuate, Prioritize, Criticize.
B68: CREATE | C68: Construct, Design, Assemble, Format, Investigate, Develop, Formulate, Create, Imagine, Produce, Invent, Plan, Build.

Sheet I1
A2: ='BL-1'!A1:L1 -> JAYARAJ ANNAPACKIAM C. S. I. COLLEGE OF ENGINEERING
A3: ='BL-1'!A2:L2 -> (Approved by AICTE, New Delhi and Affiliated to Anna University)
A4: ='BL-1'!A3:L3 -> MARGOSCHIS NAGAR, NAZARETH - 628 617
A6: ='BL-1'!A4:L4 -> DEPARTMENT OF ARTIFICIAL INTELLIGENCE AND DATA SCIENCE
A7: MARK LIST
A8: CONTINUOUS ASSESSMENT TEST - I
A10: ='BL-1'!A8:H8 -> COURSE CODE / NAME: CW3551 DATA AND INFORMATION SECURITY | L10: BATCH: | N10: 2023-27 | S10: SEM: | T10: 5
A11: ='BL-1'!A9:H9 -> COURSE INSTRUCTOR/DESIGNATION: G. ALISHA EVANGELINE,AP/ADS | L11: CLASS : | N11: III ADS
A13: Sl. No. | B13: Register No. | C13: Name of the Student | D13: PART - A ( 5 X 2 = 10) | I13: PART - B (8 X 5 = 40) | S13: Total (50) | T13: Total (100)
D14: 1 | E14: 2 | F14: 3 | G14: 4 | H14: 5 | I14: 6a | J14: 6b | K14: 7a | L14: 7b | M14: 8a | N14: 8b | O14: 9a | P14: 9b | Q14: 10a | R14: 10b
A15: 1 | B15: 951323243001 | C15: ABINAYA S | D15: 2 | E15: 2 | F15: 2 | G15: 2 | H15: 1 | I15: 7 | L15: 6 | M15: 5 | Q15: 12 | S15: 39 | T15: 78
A16: 2 | B16: 951323243002 | C16: ABISHEK S | D16: 2 | E16: 2 | F16: 2 | G16: 2 | H16: 1 | L16: 5 | P16: 7 | Q16: 12 | S16: 33 | T16: 66
A17: 3 | B17: 951323243003 | C17: AJEETHA S | D17: 2 | E17: 2 | F17: 2 | G17: 2 | H17: 2 | J17: 5 | L17: 7 | N17: 7 | P17: 7 | Q17: 12 | S17: 48 | T17: 96
A18: 4 | B18: 951323243004 | C18: AJIM FAYAZ K M S
A19: 5 | B19: 951323243005 | C19: ALPHONES CRUZ NAVEEN J | D19: 1 | H19: 0 | Q19: 2 | S19: 3 | T19: 6
A20: 6 | B20: 951323243006 | C20: ANGEL AGNES D | D20: 2 | E20: 2 | F20: 2 | G20: 2 | H20: 1 | J20: 5 | L20: 7 | M20: 7 | O20: 5 | Q20: 12 | S20: 44 | T20: 88
A21: 7 | B21: 951323243007 | C21: ANUSHA P | D21: 2 | E21: 2 | F21: 2 | G21: 2 | H21: 2 | I21: 7 | L21: 7 | M21: 7 | O21: 7 | Q21: 12 | S21: 50 | T21: 100
A22: 8 | B22: 951323243008 | C22: ARIBA M | D22: 2 | E22: 1 | F22: 2 | G22: 2 | H22: 1 | I22: 1 | L22: 7 | M22: 7 | P22: 7 | Q22: 12 | S22: 42 | T22: 84
A23: 9 | B23: 951323243009 | C23: BALADHARSHINI S | D23: 1 | E23: 1 | F23: 2 | G23: 1 | H23: 1 | I23: 7 | K23: 6 | M23: 3 | P23: 7 | R23: 12 | S23: 41 | T23: 82
A24: 10 | B24: 951323243010 | C24: BALASANKAR AYYAPPAN M | D24: 2 | E24: 2 | F24: 2 | G24: 2 | H24: 1 | J24: 6 | L24: 7 | N24: 2 | O24: 7 | Q24: 12 | S24: 43 | T24: 86
A25: 11 | B25: 951323243011 | C25: BALA SRI RAM G | E25: 1 | F25: 2 | H25: 0 | S25: 3 | T25: 6
A26: 12 | B26: 951323243012 | C26: BENJAMINE FRANKLIN C | D26: 2 | E26: 2 | F26: 2 | G26: 2 | H26: 2 | L26: 7 | P26: 7 | Q26: 12 | S26: 36 | T26: 72
A27: 13 | B27: 951323243013 | C27: CATHRINE R | D27: 2 | E27: 2 | F27: 2 | G27: 2 | H27: 2 | I27: 7 | K27: 7 | M27: 7 | P27: 6 | R27: 11 | S27: 48 | T27: 96
A28: 14 | B28: 951323243014 | C28: CHENGALESWARI K | D28: 1 | E28: 2 | F28: 2 | G28: 2 | H28: 1 | L28: 7 | N28: 7 | P28: 7 | Q28: 12 | S28: 41 | T28: 82
A29: 15 | B29: 951323243015 | C29: DEVI L | D29: 1 | E29: 1 | F29: 2 | G29: 2 | H29: 2 | I29: 1 | K29: 6 | M29: 7 | O29: 6 | Q29: 11 | S29: 39 | T29: 78
A30: 16 | B30: 951323243016 | C30: DHARUN S | D30: 1 | E30: 1 | F30: 2 | G30: 1 | H30: 1 | L30: 3 | P30: 5 | Q30: 11 | S30: 25 | T30: 50
A31: 17 | B31: 951323243017 | C31: EAKANTHALINGAM R | D31: 1 | E31: 2 | F31: 2 | G31: 1 | H31: 2 | J31: 1 | L31: 4 | N31: 6 | O31: 6 | Q31: 7 | S31: 32 | T31: 64
A32: 18 | B32: 951323243018 | C32: EFRIN THANASEKARAN J | D32: 2 | E32: 2 | F32: 2 | G32: 2 | H32: 2 | I32: 7 | L32: 7 | N32: 7 | P32: 7 | Q32: 6 | S32: 44 | T32: 88
A33: 19 | B33: 951323243019 | C33: GAYATHRI M | D33: 2 | E33: 2 | F33: 2 | G33: 2 | H33: 1 | I33: 5 | K33: 7 | M33: 7 | P33: 5 | R33: 10 | S33: 43 | T33: 86
A34: 20 | B34: 951323243020 | C34: GOKILA G | D34: 2 | E34: 2 | F34: 2 | G34: 2 | H34: 2 | I34: 7 | L34: 5 | N34: 7 | P34: 7 | Q34: 12 | S34: 48 | T34: 96
A35: 21 | B35: 951323243021 | C35: GOWRI KRISHNAVENI N | D35: 2 | E35: 2 | F35: 2 | G35: 2 | H35: 2 | I35: 7 | L35: 7 | M35: 7 | O35: 7 | Q35: 12 | S35: 50 | T35: 100
A36: 22 | B36: 951323243022 | C36: HEART BRIGHT MERCY S | D36: 2 | E36: 2 | F36: 2 | G36: 2 | H36: 1 | J36: 5 | L36: 1 | M36: 6 | P36: 7 | R36: 12 | S36: 40 | T36: 80
A37: 23 | B37: 951323243023 | C37: INFANT EBINESH R
A38: 24 | B38: 951323243024 | C38: JAI SURYA N | D38: 1 | E38: 1 | F38: 2 | G38: 1 | H38: 1 | I38: 0 | L38: 1 | N38: 1 | P38: 6 | Q38: 12 | S38: 26 | T38: 52
A39: 25 | B39: 951323243025 | C39: JANI ALICE THIRSA J | D39: 2 | E39: 1 | F39: 2 | H39: 1 | J39: 3 | K39: 6 | M39: 7 | P39: 7 | Q39: 12 | S39: 41 | T39: 82
A40: 26 | B40: 951323243026 | C40: JEBA A | D40: 2 | E40: 2 | F40: 2 | G40: 2 | H40: 2 | I40: 6 | L40: 6 | M40: 7 | O40: 7 | Q40: 12 | S40: 48 | T40: 96
A41: 27 | B41: 951323243027 | C41: JENIFER E
A42: 28 | B42: 951323243028 | C42: JENITTA CATHERIN R | D42: 1 | E42: 0 | H42: 1 | J42: 5 | L42: 4 | M42: 4 | P42: 7 | R42: 12 | S42: 34 | T42: 68
A43: 29 | B43: 951323243029 | C43: JEYACHITHRA K | D43: 2 | E43: 2 | F43: 2 | G43: 2 | H43: 2 | I43: 7 | L43: 7 | M43: 7 | O43: 7 | Q43: 12 | S43: 50 | T43: 100
A44: 30 | B44: 951323243030 | C44: JOSVA PRINCE R
...

Sheet I2
A2: ='BL-1'!A1:L1 -> JAYARAJ ANNAPACKIAM C. S. I. COLLEGE OF ENGINEERING
A3: ='BL-1'!A2:L2 -> (Approved by AICTE, New Delhi and Affiliated to Anna University)
A4: ='BL-1'!A3:L3 -> MARGOSCHIS NAGAR, NAZARETH - 628 617
A6: ='BL-1'!A4:L4 -> DEPARTMENT OF ARTIFICIAL INTELLIGENCE AND DATA SCIENCE
A7: MARK LIST
A8: CONTINUOUS ASSESSMENT TEST - II
A10: ='I1'!A10:J10 -> COURSE CODE / NAME: CW3551 DATA AND INFORMATION SECURITY | L10: BATCH: | N10: ='I1'!N10 -> 2023-27 | S10: SEM: | T10: ='I1'!T10 -> 5
A11: ='BL-1'!A9:H9 -> COURSE INSTRUCTOR/DESIGNATION: G. ALISHA EVANGELINE,AP/ADS | L11: CLASS : | N11: ='I1'!N11 -> III ADS
A13: Sl. No. | B13: Register No. | C13: Name of the Student | D13: PART - A ( 5 X 2 = 10) | I13: PART - B (8 X 5 = 40) | S13: Total (50) | T13: Total (100)
D14: 1 | E14: 2 | F14: 3 | G14: 4 | H14: 5 | I14: 6a | J14: 6b | K14: 7a | L14: 7b | M14: 8a | N14: 8b | O14: 9a | P14: 9b | Q14: 10a | R14: 10b
A15: 1 | B15: ='I1'!B15 -> 951323243001 | C15: ='I1'!C15 -> ABINAYA S | D15: 2 | E15: 1 | G15: 1 | I15: 6 | L15: 5 | Q15: 11 | S15: 26 | T15: 52
A16: 2 | B16: ='I1'!B16 -> 951323243002 | C16: ='I1'!C16 -> ABISHEK S | T16: AB
A17: 3 | B17: ='I1'!B17 -> 951323243003 | C17: ='I1'!C17 -> AJEETHA S | T17: AB
A18: 4 | B18: ='I1'!B18 -> 951323243004 | C18: ='I1'!C18 -> AJIM FAYAZ K M S | D18: 2 | E18: 2 | F18: 2 | G18: 2 | H18: 2 | O18: 4 | S18: 14 | T18: 28
A19: 5 | B19: ='I1'!B19 -> 951323243005 | C19: ='I1'!C19 -> ALPHONES CRUZ NAVEEN J | D19: 1 | E19: 2 | F19: 2 | G19: 2 | H19: 1 | I19: 6 | S19: 14 | T19: 28
A20: 6 | B20: ='I1'!B20 -> 951323243006 | C20: ='I1'!C20 -> ANGEL AGNES D | D20: 2 | E20: 1 | F20: 2 | G20: 2 | H20: 1 | I20: 7 | K20: 6 | N20: 5 | P20: 6 | Q20: 11 | S20: 43 | T20: 86
A21: 7 | B21: ='I1'!B21 -> 951323243007 | C21: ='I1'!C21 -> ANUSHA P | D21: 2 | E21: 1 | F21: 2 | G21: 2 | H21: 2 | I21: 7 | L21: 7 | N21: 7 | O21: 7 | Q21: 12 | S21: 49 | T21: 98
A22: 8 | B22: ='I1'!B22 -> 951323243008 | C22: ='I1'!C22 -> ARIBA M | D22: 1 | G22: 1 | H22: 1 | I22: 5 | L22: 7 | O22: 7 | Q22: 12 | S22: 34 | T22: 68
A23: 9 | B23: ='I1'!B23 -> 951323243009 | C23: ='I1'!C23 -> BALADHARSHINI S | D23: 1 | E23: 1 | F23: 2 | G23: 2 | H23: 1 | I23: 6 | K23: 6 | N23: 6 | O23: 6 | Q23: 11 | S23: 42 | T23: 84
A24: 10 | B24: ='I1'!B24 -> 951323243010 | C24: ='I1'!C24 -> BALASANKAR AYYAPPAN M | D24: 2 | E24: 2 | F24: 1 | G24: 2 | H24: 2 | I24: 4 | L24: 2 | M24: 6 | O24: 7 | R24: 11 | S24: 39 | T24: 78
A25: 11 | B25: ='I1'!B25 -> 951323243011 | C25: ='I1'!C25 -> BALA SRI RAM G | D25: 2 | E25: 1 | F25: 2 | G25: 1 | H25: 2 | Q25: 11 | S25: 21 | T25: 42
A26: 12 | B26: ='I1'!B26 -> 951323243012 | C26: ='I1'!C26 -> BENJAMINE FRANKLIN C | D26: 2 | E26: 2 | F26: 1 | G26: 2 | H26: 2 | L26: 2 | O26: 6 | R26: 10 | S26: 27 | T26: 54
A27: 13 | B27: ='I1'!B27 -> 951323243013 | C27: ='I1'!C27 -> CATHRINE R | D27: 1 | E27: 1 | F27: 1 | G27: 1 | H27: 1 | I27: 6 | K27: 6 | N27: 7 | O27: 2 | Q27: 10 | S27: 36 | T27: 72
A28: 14 | B28: ='I1'!B28 -> 951323243014 | C28: ='I1'!C28 -> CHENGALESWARI K | D28: 2 | E28: 2 | F28: 2 | G28: 2 | H28: 2 | I28: 7 | L28: 7 | N28: 7 | O28: 7 | Q28: 12 | S28: 50 | T28: 100
A29: 15 | B29: ='I1'!B29 -> 951323243015 | C29: ='I1'!C29 -> DEVI L | G29: 1 | H29: 1 | I29: 6 | O29: 5 | Q29: 12 | S29: 25 | T29: 50
A30: 16 | B30: ='I1'!B30 -> 951323243016 | C30: ='I1'!C30 -> DHARUN S | T30: AB
A31: 17 | B31: ='I1'!B31 -> 951323243017 | C31: ='I1'!C31 -> EAKANTHALINGAM R | D31: 2 | E31: 1 | F31: 2 | G31: 1 | H31: 2 | L31: 1 | O31: 3 | R31: 8 | S31: 20 | T31: 40
A32: 18 | B32: ='I1'!B32 -> 951323243018 | C32: ='I1'!C32 -> EFRIN THANASEKARAN J | E32: 1 | F32: 1 | G32: 2 | H32: 1 | I32: 6 | O32: 5 | Q32: 9 | S32: 25 | T32: 50
A33: 19 | B33: ='I1'!B33 -> 951323243019 | C33: ='I1'!C33 -> GAYATHRI M | D33: 1 | E33: 2 | F33: 2 | G33: 2 | H33: 2 | I33: 5 | L33: 3 | N33: 5 | O33: 4 | Q33: 12 | S33: 38 | T33: 76
A34: 20 | B34: ='I1'!B34 -> 951323243020 | C34: ='I1'!C34 -> GOKILA G | D34: 2 | E34: 1 | F34: 2 | G34: 2 | H34: 2 | I34: 7 | L34: 7 | O34: 5 | Q34: 12 | S34: 40 | T34: 80
A35: 21 | B35: ='I1'!B35 -> 951323243021 | C35: ='I1'!C35 -> GOWRI KRISHNAVENI N | D35: 2 | E35: 1 | F35: 2 | G35: 2 | H35: 2 | I35: 7 | L35: 7 | N35: 7 | O35: 7 | Q35: 12 | S35: 49 | T35: 98
A36: 22 | B36: ='I1'!B36 -> 951323243022 | C36: ='I1'!C36 -> HEART BRIGHT MERCY S | T36: AB
A37: 23 | B37: ='I1'!B37 -> 951323243023 | C37: ='I1'!C37 -> INFANT EBINESH R | D37: 1 | E37: 1 | Q37: 3 | S37: 5 | T37: 10
A38: 24 | B38: ='I1'!B38 -> 951323243024 | C38: ='I1'!C38 -> JAI SURYA N | D38: 1 | E38: 1 | F38: 1 | G38: 2 | H38: 1 | I38: 4 | O38: 3 | R38: 8 | S38: 21 | T38: 42
A39: 25 | B39: ='I1'!B39 -> 951323243025 | C39: ='I1'!C39 -> JANI ALICE THIRSA J | D39: 2 | E39: 1 | F39: 2 | G39: 2 | H39: 2 | I39: 6 | K39: 2 | M39: 3 | O39: 5 | Q39: 11 | S39: 36 | T39: 72
A40: 26 | B40: ='I1'!B40 -> 951323243026 | C40: ='I1'!C40 -> JEBA A | D40: 2 | E40: 1 | F40: 2 | G40: 2 | H40: 2 | I40: 7 | L40: 7 | N40: 6 | O40: 4 | Q40: 12 | S40: 45 | T40: 90
A41: 27 | B41: ='I1'!B41 -> 951323243027 | C41: ='I1'!C41 -> JENIFER E | D41: 2 | E41: 1 | F41: 2 | G41: 2 | H41: 2 | I41: 7 | L41: 7 | N41: 7 | O41: 7 | Q41: 12 | S41: 49 | T41: 98
A42: 28 | B42: ='I1'!B42 -> 951323243028 | C42: ='I1'!C42 -> JENITTA CATHERIN R | D42: 1 | F42: 2 | G42: 1 | I42: 7 | N42: 6 | P42: 6 | Q42: 11 | S42: 34 | T42: 68
A43: 29 | B43: ='I1'!B43 -> 951323243029 | C43: ='I1'!C43 -> JEYACHITHRA K | D43: 2 | E43: 1 | F43: 2 | G43: 2 | H43: 2 | I43: 7 | L43: 7 | N43: 7 | O43: 7 | Q43: 12 | S43: 49 | T43: 98
A44: 30 | B44: ='I1'!B44 -> 951323243030 | C44: ='I1'!C44 -> JOSVA PRINCE R | D44: 1 | Q44: 9 | S44: 10 | T44: 20
...

Sheet I3
A2: ='BL-1'!A1:L1 -> JAYARAJ ANNAPACKIAM C. S. I. COLLEGE OF ENGINEERING
A3: ='BL-1'!A2:L2 -> (Approved by AICTE, New Delhi and Affiliated to Anna University)
A4: ='BL-1'!A3:L3 -> MARGOSCHIS NAGAR, NAZARETH - 628 617
A6: ='BL-1'!A4:L4 -> DEPARTMENT OF ARTIFICIAL INTELLIGENCE AND DATA SCIENCE
A7: MARK LIST
A8: INTERNAL ASSESSMENT TEST - III
A10: ='I1'!A10:J10 -> COURSE CODE / NAME: CW3551 DATA AND INFORMATION SECURITY | L10: BATCH: | N10: ='I1'!N10 -> 2023-27 | S10: SEM: | T10: ='I1'!T10 -> 5
A11: ='BL-1'!A9:H9 -> COURSE INSTRUCTOR/DESIGNATION: G. ALISHA EVANGELINE,AP/ADS | L11: CLASS : | N11: ='I1'!N11 -> III ADS
A13: Sl. No. | B13: Register No. | C13: Name of the Student | D13: PART - A ( 5 X 2 = 10) | I13: PART - B (8 X 5 = 40) | S13: Total (50) | T13: Total (100)
D14: 1 | E14: 2 | F14: 3 | G14: 4 | H14: 5 | I14: 6a | J14: 6b | K14: 7a | L14: 7b | M14: 8a | N14: 8b | O14: 9a | P14: 9b | Q14: 10a | R14: 10b
A15: 1 | B15: ='I1'!B15 -> 951323243001 | C15: ='I1'!C15 -> ABINAYA S
A16: 2 | B16: ='I1'!B16 -> 951323243002 | C16: ='I1'!C16 -> ABISHEK S
A17: 3 | B17: ='I1'!B17 -> 951323243003 | C17: ='I1'!C17 -> AJEETHA S
A18: 4 | B18: ='I1'!B18 -> 951323243004 | C18: ='I1'!C18 -> AJIM FAYAZ K M S
A19: 5 | B19: ='I1'!B19 -> 951323243005 | C19: ='I1'!C19 -> ALPHONES CRUZ NAVEEN J
A20: 6 | B20: ='I1'!B20 -> 951323243006 | C20: ='I1'!C20 -> ANGEL AGNES D
A21: 7 | B21: ='I1'!B21 -> 951323243007 | C21: ='I1'!C21 -> ANUSHA P
A22: 8 | B22: ='I1'!B22 -> 951323243008 | C22: ='I1'!C22 -> ARIBA M
A23: 9 | B23: ='I1'!B23 -> 951323243009 | C23: ='I1'!C23 -> BALADHARSHINI S
A24: 10 | B24: ='I1'!B24 -> 951323243010 | C24: ='I1'!C24 -> BALASANKAR AYYAPPAN M
A25: 11 | B25: ='I1'!B25 -> 951323243011 | C25: ='I1'!C25 -> BALA SRI RAM G
A26: 12 | B26: ='I1'!B26 -> 951323243012 | C26: ='I1'!C26 -> BENJAMINE FRANKLIN C
... A53: 39 | B53: ='I1'!B53 -> 951323243039 | C53: ='I1'!C53 -> MERLIN HEPSIBA K
A54: 40 | B54: ='I1'!#REF! -> #REF! | C54: ='I1'!#REF! -> #REF!
A55: 41 | B55: ='I1'!B54 -> 951323243042 | C55: ='I1'!C54 -> MUTHUPRASANNA M
A56: 42 | B56: ='I1'!B55 -> 951323243043 | C56: ='I1'!C55 -> MUTHURAJ M
A57: 43 | B57: ='I1'!#REF! -> #REF! | C57: ='I1'!#REF! -> #REF!
A58: 44 | B58: ='I1'!B56 -> 951323243045 | C58: ='I1'!C56 -> PONKEERTHANA B
A59: 45 | B59: ='I1'!B57 -> 951323243046 | C59: ='I1'!C57 -> POORANATRIFFIE P
A60: 46 | B60: ='I1'!B58 -> 951323243047 | C60: ='I1'!C58 -> RACKLAND T
A61: 47 | B61: ='I1'!B59 -> 951323243048 | C61: ='I1'!C59 -> RAJA SUNDAR K
A62: 48 | B62: ='I1'!B60 -> 951323243049 | C62: ='I1'!C60 -> RAMALINGAM B
A63: 49 | B63: ='I1'!B61 -> 951323243050 | C63: ='I1'!C61 -> SELVAM GRACELIN S
A64: 50 | B64: ='I1'!B62 -> 951323243051 | C64: ='I1'!C62 -> SHANKAR V
A65: 51 | B65: ='I1'!B63 -> 951323243052 | C65: ='I1'!C63 -> SINDHUJA RAJASUMANA R
A66: 52 | B66: ='I1'!B64 -> 951323243053 | C66: ='I1'!C64 -> SNEGA G
A67: 53 | B67: ='I1'!B65 -> 951323243054 | C67: ='I1'!C65 -> SUBRAMANIAN V
A68: 54 | B68: ='I1'!B66 -> 951323243055 | C68: ='I1'!C66 -> SUGAN RAJ H
A69: 55 | B69: ='I1'!B67 -> 951323243056 | C69: ='I1'!C67 -> THOMAS KOILRAJ J
... A73: 59 | B73: ='I1'!B71 -> 951323243060 | C73: ='I1'!C71 -> VIJITHA BLESSY V
...

Sheet IAT-1
B1: ='BL-1'!A1 -> JAYARAJ ANNAPACKIAM C. S. I. COLLEGE OF ENGINEERING
B2: ='BL-1'!A2 -> (Approved by AICTE, New Delhi and Affiliated to Anna University)
B3: ='BL-1'!A3 -> MARGOSCHIS NAGAR, NAZARETH - 628 617
B4: ='BL-1'!A4 -> DEPARTMENT OF ARTIFICIAL INTELLIGENCE AND DATA SCIENCE
B5: CO ATTAINMENT
B6: INTERNAL ASSESSMENT TEST - I
A8: ='I1'!A10:J10 -> COURSE CODE / NAME: CW3551 DATA AND INFORMATION SECURITY | G8: ='BL-1'!I9 -> CLASS : III ADS | K8: ='BL-1'!I8 -> BATCH: 2023-2027 | O8: ='BL-1'!M8 -> SEM:05
A9: ='I1'!A11:J11 -> COURSE INSTRUCTOR/DESIGNATION: G. ALISHA EVANGELINE,AP/ADS | F9: ='BL-1'!M9 -> DATE: | G9: 20/09/2025 | J9: ='BL-1'!O9 -> TIME: | K9: 11:15-12:45 | O9: No. of Students in the Class: 57 | Z9: =COUNTIF('I1'!C15:C72,"*") -> 57
A11: COURSE OUTCOMES: | O11: Attainment Level | Q11: Description | AD11: Correlation Level
A12: ='BL-1'!A12 -> CO 1 | B12: ='BL-1'!B12 -> Understand the basics of data and information security | O12: 1 | Q12: Students scoring more than 40% marks in the relevant CO | AD12: Slight (1)
A13: ='BL-1'!A13 -> CO 2 | B13: ='BL-1'!B13 -> Understand the legal, ethical and professional issues in information security | O13: 2 | Q13: Students scoring more than 50% marks in the relevant CO | S13: Students scoring more than 50% marks in the relevant CO | AD13: Moderate (2)
A14: ='BL-1'!A14 -> CO 3 | B14: ='BL-1'!B14 -> Understand the various authentication schemes to simulate different applications | O14: 3 | Q14: Students scoring more than 60% marks in the relevant CO | S14: Students scoring more than 60% marks in the relevant CO | AD14: Substantial (3)
A15: ='BL-1'!A15 -> CO 4 | B15: ='BL-1'!B15 -> Understand various security practices and system security standards
A16: ='BL-1'!A16 -> CO 5 | B16: ='BL-1'!B16 -> Understand the web security protocols for E-commerce applications
D18: BLOOMS LEVEL
D19: L1: REMEMBER | E19: L2: UNDERSTAND | G19: L3: APPLY | I19: L4: ANALYSE | K19: L5: EVALUATE | M19: L6: CREATE | P19: MARK ALLOCATION
B20: S. No | C20: Reg. No. | D20: Name of the Student | E20: IAT-I | F20: Part A | K20: Part B | P20: CO 1 Attainment | R20: CO 2 Attainment | T20: CO 3 Attainment | V20: CO 4 Attainment | X20: CO 5 Attainment | Z20: TOTAL MARK
E21: Q.No. | F21: 1 | G21: 2 | H21: 3 | I21: 4 | J21: 5 | K21: 6 | L21: 7 | M21: 8 | N21: 9 | O21: 10
E23: CO | F23: =IF('BL-1'!C20="ü",1,IF('BL-1'!#REF!="ü",2,IF('BL-1'!C22="ü",3,IF('BL-1'!C23="ü",4,IF('BL-1'!C24="ü",5,0))))) -> 1 | G23: =IF('BL-1'!D20="ü",1,IF('BL-1'!#REF!="ü",2,IF('BL-1'!D22="ü",3,IF('BL-1'!D23="ü",4,IF('BL-1'!D24="ü",5,0))))) -> 1 | H23: =IF('BL-1'!E20="ü",1,IF('BL-1'!E21="ü",2,IF('BL-1'!E22="ü",3,IF('BL-1'!E23="ü",4,IF('BL-1'!E24="ü",5,0))))) -> 2 | I23: =IF('BL-1'!F20="ü",1,IF('BL-1'!F21="ü",2,IF('BL-1'!F22="ü",3,IF('BL-1'!F23="ü",4,IF('BL-1'!F24="ü",5,0))))) -> 2 | J23: =IF('BL-1'!G20="ü",1,IF('BL-1'!G21="ü",2,IF('BL-1'!G22="ü",3,IF('BL-1'!G23="ü",4,IF('BL-1'!G24="ü",5,0))))) -> 3 | K23: =IF('BL-1'!H20="ü",1,IF('BL-1'!H21="ü",2,IF('BL-1'!H22="ü",3,IF('BL-1'!H23="ü",4,IF('BL-1'!H24="ü",5,0))))) -> 1 | L23: =IF('BL-1'!I20="ü",1,IF('BL-1'!I21="ü",2,IF('BL-1'!I22="ü",3,IF('BL-1'!I23="ü",4,IF('BL-1'!I24="ü",5,0))))) -> 2 | M23: =IF('BL-1'!J20="ü",1,IF('BL-1'!J21="ü",2,IF('BL-1'!J22="ü",3,IF('BL-1'!J23="ü",4,IF('BL-1'!J24="ü",5,0))))) -> 2 | N23: =IF('BL-1'!K20<>"ü",1,IF('BL-1'!K21="ü",2,IF('BL-1'!K22="ü",3,IF('BL-1'!K23="ü",4,IF('BL-1'!K24="ü",5,0))))) -> 1 | O23: =IF('BL-1'!L20="ü",1,IF('BL-1'!L21="ü",2,IF('BL-1'!L22="ü",3,IF('BL-1'!L23="ü",4,IF('BL-1'!L24="ü",5,0))))) -> 1
E24: BL | F24: =IF('BL-1'!C25="ü","L1",IF('BL-1'!C26="ü","L2",IF('BL-1'!C27="ü","L3",IF('BL-1'!C28="ü","L4",IF('BL-1'!C29="ü","L5","L6"))))) -> L2 | G24: =IF('BL-1'!D25="ü","L1",IF('BL-1'!D26="ü","L2",IF('BL-1'!D27="ü","L3",IF('BL-1'!D28="ü","L4",IF('BL-1'!D29="ü","L5","L6"))))) -> L2 | H24: =IF('BL-1'!E25="ü","L1",IF('BL-1'!E26="ü","L2",IF('BL-1'!E27="ü","L3",IF('BL-1'!E28="ü","L4",IF('BL-1'!E29="ü","L5","L6"))))) -> L1 | I24: =IF('BL-1'!F25="ü","L1",IF('BL-1'!F26="ü","L2",IF('BL-1'!F27="ü","L3",IF('BL-1'!F28="ü","L4",IF('BL-1'!F29="ü","L5","L6"))))) -> L2 | J24: =IF('BL-1'!G25="ü","L1",IF('BL-1'!G26="ü","L2",IF('BL-1'!G27="ü","L3",IF('BL-1'!G28="ü","L4",IF('BL-1'!G29="ü","L5","L6"))))) -> L2 | K24: =IF('BL-1'!H25="ü","L1",IF('BL-1'!H26="ü","L2",IF('BL-1'!H27="ü","L3",IF('BL-1'!H28="ü","L4",IF('BL-1'!H29="ü","L5","L6"))))) -> L2 | L24: =IF('BL-1'!I25="ü","L1",IF('BL-1'!I26="ü","L2",IF('BL-1'!I27="ü","L3",IF('BL-1'!I28="ü","L4",IF('BL-1'!I29="ü","L5","L6"))))) -> L2 | M24: =IF('BL-1'!J25="ü","L1",IF('BL-1'!J26="ü","L2",IF('BL-1'!J27="ü","L3",IF('BL-1'!J28="ü","L4",IF('BL-1'!J29="ü","L5","L6"))))) -> L2 | ... O24: =IF('BL-1'!L25="ü","L1",IF('BL-1'!L26="ü","L2",IF('BL-1'!L27="ü","L3",IF('BL-1'!L28="ü","L4",IF('BL-1'!L29="ü","L5","L6"))))) -> L2
E25: MARK | F25: 2 | G25: 2 | H25: 2 | I25: 2 | J25: 2 | K25: 7 | L25: 7 | M25: 7 | N25: 7 | O25: 12 | P25: =SUMIF('BL-1'!$C$20:$L$20,"*",'IAT-1'!F25:O25) -> 23 | Q25: 100 | R25: =SUMIF('BL-1'!$C$21:$L$21,"*",'IAT-1'!F25:O25) -> 18 | S25: 100 | T25: =SUMIF('BL-1'!$C$22:$L$22,"*",'IAT-1'!F25:O25) -> 9 | U25: 100 | V25: =SUMIF('BL-1'!$C$23:$L$23,"*",'IAT-1'!F25:O25) -> 0 | W25: 100 | X25: =SUMIF('BL-1'!$C$24:$L$24,"*",'IAT-1'!F25:O25) -> 0 | Y25: 100 | Z25: 50 | AA25: =Z25*2 -> 100
B26: 1 | C26: ='I1'!B15 -> 951323243001 | D26: ='I1'!C15 -> ABINAYA S | F26: ='I1'!D15 -> 2 | G26: ='I1'!E15 -> 2 | H26: ='I1'!F15 -> 2 | I26: ='I1'!G15 -> 2 | J26: ='I1'!H15 -> 1 | K26: ='I1'!I15+'I1'!J15 -> 7 | L26: ='I1'!K15+'I1'!L15 -> 6 | M26: ='I1'!M15+'I1'!N15 -> 5 | N26: ='I1'!O15+'I1'!P15 -> 0 | O26: ='I1'!Q15+'I1'!R15 -> 12 | P26: =SUMIF('BL-1'!$C$20:$L$20,"*",'IAT-1'!F26:O26) -> 23 | Q26: =ROUND(IFERROR(P26/P$25,0)*100,1) -> 100 | R26: =SUMIF('BL-1'!$C$21:$L$21,"*",'IAT-1'!F26:O26) -> 15 | S26: =ROUND(IFERROR(R26/R$25,0)*100,1) -> 83.3 | T26: =SUMIF('BL-1'!$C$22:$L$22,"*",'IAT-1'!F26:O26) -> 1 | U26: =ROUND(IFERROR(T26/T$25,0)*100,1) -> 11.1 | V26: =SUMIF('BL-1'!$C$23:$L$23,"*",'IAT-1'!F26:O26) -> 0 | W26: =ROUND(IFERROR(V26/V$25,0)*100,1) -> 0 | X26: =SUMIF('BL-1'!$C$24:$L$24,"*",'IAT-1'!F26:O26) -> 0 | Y26: =ROUND(IFERROR(X26/X$25,0)*100,1) -> 0 | Z26: =SUM(P26,R26,T26,V26,X26) -> 39 | AA26: =Z26*2 -> 78
B27: 2 | C27: ='I1'!B16 -> 951323243002 | D27: ='I1'!C16 -> ABISHEK S | F27: ='I1'!D16 -> 2 | G27: ='I1'!E16 -> 2 | H27: ='I1'!F16 -> 2 | I27: ='I1'!G16 -> 2 | J27: ='I1'!H16 -> 1 | K27: ='I1'!I16+'I1'!J16 -> 0 | L27: ='I1'!K16+'I1'!L16 -> 5 | M27: ='I1'!M16+'I1'!N16 -> 0 | N27: ='I1'!O16+'I1'!P16 -> 7 | O27: ='I1'!Q16+'I1'!R16 -> 12 | P27: =SUMIF('BL-1'!$C$20:$L$20,"*",'IAT-1'!F27:O27) -> 16 | Q27: =ROUND(IFERROR(P27/P$25,0)*100,1) -> 69.6 | R27: =SUMIF('BL-1'!$C$21:$L$21,"*",'IAT-1'!F27:O27) -> 9 | S27: =ROUND(IFERROR(R27/R$25,0)*100,1) -> 50 | T27: =SUMIF('BL-1'!$C$22:$L$22,"*",'IAT-1'!F27:O27) -> 8 | U27: =ROUND(IFERROR(T27/T$25,0)*100,1) -> 88.9 | V27: =SUMIF('BL-1'!$C$23:$L$23,"*",'IAT-1'!F27:O27) -> 0 | W27: =ROUND(IFERROR(V27/V$25,0)*100,1) -> 0 | X27: =SUMIF('BL-1'!$C$24:$L$24,"*",'IAT-1'!F27:O27) -> 0 | Y27: =ROUND(IFERROR(X27/X$25,0)*100,1) -> 0 | Z27: =SUM(P27,R27,T27,V27,X27) -> 33 | AA27: =Z27*2 -> 66
B28: 3 | C28: ='I1'!B17 -> 951323243003 | D28: ='I1'!C17 -> AJEETHA S | F28: ='I1'!D17 -> 2 | G28: ='I1'!E17 -> 2 | H28: ='I1'!F17 -> 2 | I28: ='I1'!G17 -> 2 | J28: ='I1'!H17 -> 2 | K28: ='I1'!I17+'I1'!J17 -> 5 | L28: ='I1'!K17+'I1'!L17 -> 7 | M28: ='I1'!M17+'I1'!N17 -> 7 | N28: ='I1'!O17+'I1'!P17 -> 7 | O28: ='I1'!Q17+'I1'!R17 -> 12 | P28: =SUMIF('BL-1'!$C$20:$L$20,"*",'IAT-1'!F28:O28) -> 21 | Q28: =ROUND(IFERROR(P28/P$25,0)*100,1) -> 91.3 | R28: =SUMIF('BL-1'!$C$21:$L$21,"*",'IAT-1'!F28:O28) -> 18 | S28: =ROUND(IFERROR(R28/R$25,0)*100,1) -> 100 | T28: =SUMIF('BL-1'!$C$22:$L$22,"*",'IAT-1'!F28:O28) -> 9 | U28: =ROUND(IFERROR(T28/T$25,0)*100,1) -> 100 | V28: =SUMIF('BL-1'!$C$23:$L$23,"*",'IAT-1'!F28:O28) -> 0 | W28: =ROUND(IFERROR(V28/V$25,0)*100,1) -> 0 | X28: =SUMIF('BL-1'!$C$24:$L$24,"*",'IAT-1'!F28:O28) -> 0 | Y28: =ROUND(IFERROR(X28/X$25,0)*100,1) -> 0 | Z28: =SUM(P28,R28,T28,V28,X28) -> 48 | AA28: =Z28*2 -> 96
B29: 4 | C29: ='I1'!B18 -> 951323243004 | D29: ='I1'!C18 -> AJIM FAYAZ K M S | F29: ='I1'!D18 -> 0 | G29: ='I1'!E18 -> 0 | H29: ='I1'!F18 -> 0 | I29: ='I1'!G18 -> 0 | J29: ='I1'!H18 -> 0 | K29: ='I1'!I18+'I1'!J18 -> 0 | L29: ='I1'!K18+'I1'!L18 -> 0 | M29: ='I1'!M18+'I1'!N18 -> 0 | N29: ='I1'!O18+'I1'!P18 -> 0 | O29: ='I1'!Q18+'I1'!R18 -> 0 | P29: =SUMIF('BL-1'!$C$20:$L$20,"*",'IAT-1'!F29:O29) -> 0 | Q29: =ROUND(IFERROR(P29/P$25,0)*100,1) -> 0 | R29: =SUMIF('BL-1'!$C$21:$L$21,"*",'IAT-1'!F29:O29) -> 0 | S29: =ROUND(IFERROR(R29/R$25,0)*100,1) -> 0 | T29: =SUMIF('BL-1'!$C$22:$L$22,"*",'IAT-1'!F29:O29) -> 0 | U29: =ROUND(IFERROR(T29/T$25,0)*100,1) -> 0 | V29: =SUMIF('BL-1'!$C$23:$L$23,"*",'IAT-1'!F29:O29) -> 0 | W29: =ROUND(IFERROR(V29/V$25,0)*100,1) -> 0 | X29: =SUMIF('BL-1'!$C$24:$L$24,"*",'IAT-1'!F29:O29) -> 0 | Y29: =ROUND(IFERROR(X29/X$25,0)*100,1) -> 0 | Z29: =SUM(P29,R29,T29,V29,X29) -> 0 | AA29: =Z29*2 -> 0
B30: 5 | C30: ='I1'!B19 -> 951323243005 | D30: ='I1'!C19 -> ALPHONES CRUZ NAVEEN J | F30: ='I1'!D19 -> 1 | G30: ='I1'!E19 -> 0 | H30: ='I1'!F19 -> 0 | I30: ='I1'!G19 -> 0 | J30: ='I1'!H19 -> 0 | K30: ='I1'!I19+'I1'!J19 -> 0 | L30: ='I1'!K19+'I1'!L19 -> 0 | M30: ='I1'!M19+'I1'!N19 -> 0 | N30: ='I1'!O19+'I1'!P19 -> 0 | O30: ='I1'!Q19+'I1'!R19 -> 2 | P30: =SUMIF('BL-1'!$C$20:$L$20,"*",'IAT-1'!F30:O30) -> 3 | Q30: =ROUND(IFERROR(P30/P$25,0)*100,1) -> 13 | R30: =SUMIF('BL-1'!$C$21:$L$21,"*",'IAT-1'!F30:O30) -> 0 | S30: =ROUND(IFERROR(R30/R$25,0)*100,1) -> 0 | T30: =SUMIF('BL-1'!$C$22:$L$22,"*",'IAT-1'!F30:O30) -> 0 | U30: =ROUND(IFERROR(T30/T$25,0)*100,1) -> 0 | V30: =SUMIF('BL-1'!$C$23:$L$23,"*",'IAT-1'!F30:O30) -> 0 | W30: =ROUND(IFERROR(V30/V$25,0)*100,1) -> 0 | X30: =SUMIF('BL-1'!$C$24:$L$24,"*",'IAT-1'!F30:O30) -> 0 | Y30: =ROUND(IFERROR(X30/X$25,0)*100,1) -> 0 | Z30: =SUM(P30,R30,T30,V30,X30) -> 3 | AA30: =Z30*2 -> 6
B31: 6 | C31: ='I1'!B20 -> 951323243006 | D31: ='I1'!C20 -> ANGEL AGNES D | F31: ='I1'!D20 -> 2 | G31: ='I1'!E20 -> 2 | H31: ='I1'!F20 -> 2 | I31: ='I1'!G20 -> 2 | J31: ='I1'!H20 -> 1 | K31: ='I1'!I20+'I1'!J20 -> 5 | L31: ='I1'!K20+'I1'!L20 -> 7 | M31: ='I1'!M20+'I1'!N20 -> 7 | N31: ='I1'!O20+'I1'!P20 -> 5 | O31: ='I1'!Q20+'I1'!R20 -> 12 | P31: =SUMIF('BL-1'!$C$20:$L$20,"*",'IAT-1'!F31:O31) -> 21 | Q31: =ROUND(IFERROR(P31/P$25,0)*100,1) -> 91.3 | R31: =SUMIF('BL-1'!$C$21:$L$21,"*",'IAT-1'!F31:O31) -> 18 | S31: =ROUND(IFERROR(R31/R$25,0)*100,1) -> 100 | T31: =SUMIF('BL-1'!$C$22:$L$22,"*",'IAT-1'!F31:O31) -> 6 | U31: =ROUND(IFERROR(T31/T$25,0)*100,1) -> 66.7 | V31: =SUMIF('BL-1'!$C$23:$L$23,"*",'IAT-1'!F31:O31) -> 0 | W31: =ROUND(IFERROR(V31/V$25,0)*100,1) -> 0 | X31: =SUMIF('BL-1'!$C$24:$L$24,"*",'IAT-1'!F31:O31) -> 0 | Y31: =ROUND(IFERROR(X31/X$25,0)*100,1) -> 0 | Z31: =SUM(P31,R31,T31,V31,X31) -> 45 | AA31: =Z31*2 -> 90
B32: 7 | C32: ='I1'!B21 -> 951323243007 | D32: ='I1'!C21 -> ANUSHA P | F32: ='I1'!D21 -> 2 | G32: ='I1'!E21 -> 2 | H32: ='I1'!F21 -> 2 | I32: ='I1'!G21 -> 2 | J32: ='I1'!H21 -> 2 | K32: ='I1'!I21+'I1'!J21 -> 7 | L32: ='I1'!K21+'I1'!L21 -> 7 | M32: ='I1'!M21+'I1'!N21 -> 7 | N32: ='I1'!O21+'I1'!P21 -> 7 | O32: ='I1'!Q21+'I1'!R21 -> 12 | P32: =SUMIF('BL-1'!$C$20:$L$20,"*",'IAT-1'!F32:O32) -> 23 | Q32: =ROUND(IFERROR(P32/P$25,0)*100,1) -> 100 | R32: =SUMIF('BL-1'!$C$21:$L$21,"*",'IAT-1'!F32:O32) -> 18 | S32: =ROUND(IFERROR(R32/R$25,0)*100,1) -> 100 | T32: =SUMIF('BL-1'!$C$22:$L$22,"*",'IAT-1'!F32:O32) -> 9 | U32: =ROUND(IFERROR(T32/T$25,0)*100,1) -> 100 | V32: =SUMIF('BL-1'!$C$23:$L$23,"*",'IAT-1'!F32:O32) -> 0 | W32: =ROUND(IFERROR(V32/V$25,0)*100,1) -> 0 | X32: =SUMIF('BL-1'!$C$24:$L$24,"*",'IAT-1'!F32:O32) -> 0 | Y32: =ROUND(IFERROR(X32/X$25,0)*100,1) -> 0 | Z32: =SUM(P32,R32,T32,V32,X32) -> 50 | AA32: =Z32*2 -> 100
B33: 8 | C33: ='I1'!B22 -> 951323243008 | D33: ='I1'!C22 -> ARIBA M | F33: ='I1'!D22 -> 2 | G33: ='I1'!E22 -> 1 | H33: ='I1'!F22 -> 2 | I33: ='I1'!G22 -> 2 | J33: ='I1'!H22 -> 1 | K33: ='I1'!I22+'I1'!J22 -> 1 | L33: ='I1'!K22+'I1'!L22 -> 7 | M33: ='I1'!M22+'I1'!N22 -> 7 | N33: ='I1'!O22+'I1'!P22 -> 7 | O33: ='I1'!Q22+'I1'!R22 -> 12 | P33: =SUMIF('BL-1'!$C$20:$L$20,"*",'IAT-1'!F33:O33) -> 16 | Q33: =ROUND(IFERROR(P33/P$25,0)*100,1) -> 69.6 | R33: =SUMIF('BL-1'!$C$21:$L$21,"*",'IAT-1'!F33:O33) -> 18 | S33: =ROUND(IFERROR(R33/R$25,0)*100,1) -> 100 | T33: =SUMIF('BL-1'!$C$22:$L$22,"*",'IAT-1'!F33:O33) -> 8 | U33: =ROUND(IFERROR(T33/T$25,0)*100,1) -> 88.9 | V33: =SUMIF('BL-1'!$C$23:$L$23,"*",'IAT-1'!F33:O33) -> 0 | W33: =ROUND(IFERROR(V33/V$25,0)*100,1) -> 0 | X33: =SUMIF('BL-1'!$C$24:$L$24,"*",'IAT-1'!F33:O33) -> 0 | Y33: =ROUND(IFERROR(X33/X$25,0)*100,1) -> 0 | Z33: =SUM(P33,R33,T33,V33,X33) -> 42 | AA33: =Z33*2 -> 84
B34: 9 | C34: ='I1'!B23 -> 951323243009 | D34: ='I1'!C23 -> BALADHARSHINI S | F34: ='I1'!D23 -> 1 | G34: ='I1'!E23 -> 1 | H34: ='I1'!F23 -> 2 | I34: ='I1'!G23 -> 1 | J34: ='I1'!H23 -> 1 | K34: ='I1'!I23+'I1'!J23 -> 7 | L34: ='I1'!K23+'I1'!L23 -> 6 | M34: ='I1'!M23+'I1'!N23 -> 3 | N34: ='I1'!O23+'I1'!P23 -> 7 | O34: ='I1'!Q23+'I1'!R23 -> 12 | P34: =SUMIF('BL-1'!$C$20:$L$20,"*",'IAT-1'!F34:O34) -> 21 | Q34: =ROUND(IFERROR(P34/P$25,0)*100,1) -> 91.3 | R34: =SUMIF('BL-1'!$C$21:$L$21,"*",'IAT-1'!F34:O34) -> 12 | S34: =ROUND(IFERROR(R34/R$25,0)*100,1) -> 66.7 | T34: =SUMIF('BL-1'!$C$22:$L$22,"*",'IAT-1'!F34:O34) -> 8 | U34: =ROUND(IFERROR(T34/T$25,0)*100,1) -> 88.9 | V34: =SUMIF('BL-1'!$C$23:$L$23,"*",'IAT-1'!F34:O34) -> 0 | W34: =ROUND(IFERROR(V34/V$25,0)*100,1) -> 0 | X34: =SUMIF('BL-1'!$C$24:$L$24,"*",'IAT-1'!F34:O34) -> 0 | Y34: =ROUND(IFERROR(X34/X$25,0)*100,1) -> 0 | Z34: =SUM(P34,R34,T34,V34,X34) -> 41 | AA34: =Z34*2 -> 82
B35: 10 | C35: ='I1'!B24 -> 951323243010 | D35: ='I1'!C24 -> BALASANKAR AYYAPPAN M | F35: ='I1'!D24 -> 2 | G35: ='I1'!E24 -> 2 | H35: ='I1'!F24 -> 2 | I35: ='I1'!G24 -> 2 | J35: ='I1'!H24 -> 1 | K35: ='I1'!I24+'I1'!J24 -> 6 | L35: ='I1'!K24+'I1'!L24 -> 7 | M35: ='I1'!M24+'I1'!N24 -> 2 | N35: ='I1'!O24+'I1'!P24 -> 7 | O35: ='I1'!Q24+'I1'!R24 -> 12 | P35: =SUMIF('BL-1'!$C$20:$L$20,"*",'IAT-1'!F35:O35) -> 22 | Q35: =ROUND(IFERROR(P35/P$25,0)*100,1) -> 95.7 | R35: =SUMIF('BL-1'!$C$21:$L$21,"*",'IAT-1'!F35:O35) -> 13 | S35: =ROUND(IFERROR(R35/R$25,0)*100,1) -> 72.2 | T35: =SUMIF('BL-1'!$C$22:$L$22,"*",'IAT-1'!F35:O35) -> 8 | U35: =ROUND(IFERROR(T35/T$25,0)*100,1) -> 88.9 | V35: =SUMIF('BL-1'!$C$23:$L$23,"*",'IAT-1'!F35:O35) -> 0 | W35: =ROUND(IFERROR(V35/V$25,0)*100,1) -> 0 | X35: =SUMIF('BL-1'!$C$24:$L$24,"*",'IAT-1'!F35:O35) -> 0 | Y35: =ROUND(IFERROR(X35/X$25,0)*100,1) -> 0 | Z35: =SUM(P35,R35,T35,V35,X35) -> 43 | AA35: =Z35*2 -> 86
B36: 11 | C36: ='I1'!B25 -> 951323243011 | D36: ='I1'!C25 -> BALA SRI RAM G | F36: ='I1'!D25 -> 0 | G36: ='I1'!E25 -> 1 | H36: ='I1'!F25 -> 2 | I36: ='I1'!G25 -> 0 | J36: ='I1'!H25 -> 0 | K36: ='I1'!I25+'I1'!J25 -> 0 | L36: ='I1'!K25+'I1'!L25 -> 0 | M36: ='I1'!M25+'I1'!N25 -> 0 | N36: ='I1'!O25+'I1'!P25 -> 0 | O36: ='I1'!Q25+'I1'!R25 -> 0 | P36: =SUMIF('BL-1'!$C$20:$L$20,"*",'IAT-1'!F36:O36) -> 1 | Q36: =ROUND(IFERROR(P36/P$25,0)*100,1) -> 4.3 | R36: =SUMIF('BL-1'!$C$21:$L$21,"*",'IAT-1'!F36:O36) -> 2 | S36: =ROUND(IFERROR(R36/R$25,0)*100,1) -> 11.1 | T36: =SUMIF('BL-1'!$C$22:$L$22,"*",'IAT-1'!F36:O36) -> 0 | U36: =ROUND(IFERROR(T36/T$25,0)*100,1) -> 0 | V36: =SUMIF('BL-1'!$C$23:$L$23,"*",'IAT-1'!F36:O36) -> 0 | W36: =ROUND(IFERROR(V36/V$25,0)*100,1) -> 0 | X36: =SUMIF('BL-1'!$C$24:$L$24,"*",'IAT-1'!F36:O36) -> 0 | Y36: =ROUND(IFERROR(X36/X$25,0)*100,1) -> 0 | Z36: =SUM(P36,R36,T36,V36,X36) -> 3 | AA36: =Z36*2 -> 6
B37: 12 | C37: ='I1'!B26 -> 951323243012 | D37: ='I1'!C26 -> BENJAMINE FRANKLIN C | F37: ='I1'!D26 -> 2 | G37: ='I1'!E26 -> 2 | H37: ='I1'!F26 -> 2 | I37: ='I1'!G26 -> 2 | J37: ='I1'!H26 -> 2 | K37: ='I1'!I26+'I1'!J26 -> 0 | L37: ='I1'!K26+'I1'!L26 -> 7 | M37: ='I1'!M26+'I1'!N26 -> 0 | N37: ='I1'!O26+'I1'!P26 -> 7 | O37: ='I1'!Q26+'I1'!R26 -> 12 | P37: =SUMIF('BL-1'!$C$20:$L$20,"*",'IAT-1'!F37:O37) -> 16 | Q37: =ROUND(IFERROR(P37/P$25,0)*100,1) -> 69.6 | R37: =SUMIF('BL-1'!$C$21:$L$21,"*",'IAT-1'!F37:O37) -> 11 | S37: =ROUND(IFERROR(R37/R$25,0)*100,1) -> 61.1 | T37: =SUMIF('BL-1'!$C$22:$L$22,"*",'IAT-1'!F37:O37) -> 9 | U37: =ROUND(IFERROR(T37/T$25,0)*100,1) -> 100 | V37: =SUMIF('BL-1'!$C$23:$L$23,"*",'IAT-1'!F37:O37) -> 0 | W37: =ROUND(IFERROR(V37/V$25,0)*100,1) -> 0 | X37: =SUMIF('BL-1'!$C$24:$L$24,"*",'IAT-1'!F37:O37) -> 0 | Y37: =ROUND(IFERROR(X37/X$25,0)*100,1) -> 0 | Z37: =SUM(P37,R37,T37,V37,X37) -> 36 | AA37: =Z37*2 -> 72
... B81: 56 | C81: ='I1'!B70 -> 951323243059 | D81: ='I1'!C70 -> VIJAYAPRAKASH S | F81: ='I1'!D70 -> 0 | G81: ='I1'!E70 -> 0 | H81: ='I1'!F70 -> 0 | I81: ='I1'!G70 -> 0 | J81: ='I1'!H70 -> 0 | K81: ='I1'!I70+'I1'!J70 -> 0 | L81: ='I1'!K70+'I1'!L70 -> 0 | M81: ='I1'!M70+'I1'!N70 -> 0 | N81: ='I1'!O70+'I1'!P70 -> 0 | O81: ='I1'!Q70+'I1'!R70 -> 0 | P81: =SUMIF('BL-1'!$C$20:$L$20,"*",'IAT-1'!F81:O81) -> 0 | Q81: =ROUND(IFERROR(P81/P$25,0)*100,1) -> 0 | R81: =SUMIF('BL-1'!$C$21:$L$21,"*",'IAT-1'!F81:O81) -> 0 | S81: =ROUND(IFERROR(R81/R$25,0)*100,1) -> 0 | T81: =SUMIF('BL-1'!$C$22:$L$22,"*",'IAT-1'!F81:O81) -> 0 | U81: =ROUND(IFERROR(T81/T$25,0)*100,1) -> 0 | V81: =SUMIF('BL-1'!$C$23:$L$23,"*",'IAT-1'!F81:O81) -> 0 | W81: =ROUND(IFERROR(V81/V$25,0)*100,1) -> 0 | X81: =SUMIF('BL-1'!$C$24:$L$24,"*",'IAT-1'!F81:O81) -> 0 | Y81: =ROUND(IFERROR(X81/X$25,0)*100,1) -> 0 | Z81: =SUM(P81,R81,T81,V81,X81) -> 0 | AA81: =Z81*2 -> 0
B82: 57 | C82: ='I1'!B71 -> 951323243060 | D82: ='I1'!C71 -> VIJITHA BLESSY V | F82: ='I1'!D71 -> 0 | G82: ='I1'!E71 -> 0 | H82: ='I1'!F71 -> 2 | I82: ='I1'!G71 -> 0 | J82: ='I1'!H71 -> 0 | K82: ='I1'!I73+'I1'!J73 -> 0 | L82: ='I1'!K71+'I1'!L71 -> 5 | M82: ='I1'!M71+'I1'!N71 -> 6 | N82: ='I1'!O71+'I1'!P71 -> 3 | O82: ='I1'!Q71+'I1'!R71 -> 11 | P82: =SUMIF('BL-1'!$C$20:$L$20,"*",'IAT-1'!F82:O82) -> 11 | Q82: =ROUND(IFERROR(P82/P$25,0)*100,1) -> 47.8 | R82: =SUMIF('BL-1'!$C$21:$L$21,"*",'IAT-1'!F82:O82) -> 13 | S82: =ROUND(IFERROR(R82/R$25,0)*100,1) -> 72.2 | T82: =SUMIF('BL-1'!$C$22:$L$22,"*",'IAT-1'!F82:O82) -> 3 | U82: =ROUND(IFERROR(T82/T$25,0)*100,1) -> 33.3 | V82: =SUMIF('BL-1'!$C$23:$L$23,"*",'IAT-1'!F82:O82) -> 0 | W82: =ROUND(IFERROR(V82/V$25,0)*100,1) -> 0 | X82: =SUMIF('BL-1'!$C$24:$L$24,"*",'IAT-1'!F82:O82) -> 0 | Y82: =ROUND(IFERROR(X82/X$25,0)*100,1) -> 0 | Z82: =SUM(P82,R82,T82,V82,X82) -> 27 | AA82: =Z82*2 -> 54
E83: No. of students attained more than 50% of marks in the relevant CO | Q83: =COUNTIF(Q26:Q82,">=50") -> 42 | S83: =COUNTIF(S26:S82,">=50") -> 38 | U83: =COUNTIF(U26:U82,">=50") -> 39 | W83: =COUNTIF(W26:W82,">=50") -> 0 | Y83: =COUNTIF(Y26:Y82,">=50") -> 0
E84: Percentage of students obtained more than 50% marks in relevant CO | Q84: =ROUND(IFERROR(Q83/$Z$9,0)*100,1) -> 73.7 | S84: =ROUND(IFERROR(S83/$Z$9,0)*100,1) -> 66.7 | U84: =ROUND(IFERROR(U83/$Z$9,0)*100,1) -> 68.4 | W84: =ROUND(IFERROR(W83/$Z$9,0)*100,1) -> 0 | Y84: =ROUND(IFERROR(Y83/$Z$9,0)*100,1) -> 0
E85: Correlation Level | Q85: =IF(Q84>=60,3,IF(Q84>=50,2,IF(Q84>=40,1,0))) -> 3 | S85: =IF(S84>=60,3,IF(S84>=50,2,IF(S84>=40,1,0))) -> 3 | U85: =IF(U84>=60,3,IF(U84>=50,2,IF(U84>=40,1,0))) -> 3 | W85: =IF(W84>=60,3,IF(W84>=50,2,IF(W84>=40,1,0))) -> 0 | Y85: =IF(Y84>=60,3,IF(Y84>=50,2,IF(Y84>=40,1,0))) -> 0

Sheet IAT-2
E1: ='BL-1'!A1 -> JAYARAJ ANNAPACKIAM C. S. I. COLLEGE OF ENGINEERING
E2: ='BL-1'!A2 -> (Approved by AICTE, New Delhi and Affiliated to Anna University)
E3: ='BL-1'!A3 -> MARGOSCHIS NAGAR, NAZARETH - 628 617
E4: ='BL-1'!A4 -> DEPARTMENT OF ARTIFICIAL INTELLIGENCE AND DATA SCIENCE
E5: CO ATTAINMENT
E6: INTERNAL ASSESSMENT TEST - II
A8: ='IAT-1'!A8 -> COURSE CODE / NAME: CW3551 DATA AND INFORMATION SECURITY | G8: ='BL-1'!I9 -> CLASS : III ADS | K8: ='BL-1'!I8 -> BATCH: 2023-2027 | O8: ='BL-1'!M8 -> SEM:05
A9: ='IAT-1'!A9 -> COURSE INSTRUCTOR/DESIGNATION: G. ALISHA EVANGELINE,AP/ADS | F9: ='BL-1'!M9 -> DATE: | G9: ='BL-2'!M31 -> 45758 | J9: ='BL-1'!O9 -> TIME: | K9: 11:15-12:45 | N9: No. of Students in the Class: | U9: ='IAT-1'!$Z$9 -> 57 | Z9: ='IAT-1'!Z9 -> 57
A11: COURSE OUTCOMES: | O11: Attainment Level | T11: Description | AC11: Correlation Level
A12: ='BL-1'!A12 -> CO 1 | B12: ='BL-1'!B12 -> Understand the basics of data and information security | O12: 1 | T12: Students scoring more than 40% marks in the relevant CO | V12: Students scoring more than 40% marks in the relevant CO | AC12: Slight (1)
A13: ='BL-1'!A13 -> CO 2 | B13: ='BL-1'!B13 -> Understand the legal, ethical and professional issues in information security | O13: 2 | T13: Students scoring more than 50% marks in the relevant CO | V13: Students scoring more than 50% marks in the relevant CO | AC13: Moderate (2)
A14: ='BL-1'!A14 -> CO 3 | B14: ='BL-1'!B14 -> Understand the various authentication schemes to simulate different applications | O14: 3 | T14: Students scoring more than 60% marks in the relevant CO | V14: Students scoring more than 60% marks in the relevant CO | AC14: Substantial (3)
A15: ='BL-1'!A15 -> CO 4 | B15: ='BL-1'!B15 -> Understand various security practices and system security standards
A16: ='BL-1'!A16 -> CO 5 | B16: ='BL-1'!B16 -> Understand the web security protocols for E-commerce applications
D18: BLOOMS LEVEL
D19: L1: REMEMBER | E19: L2: UNDERSTAND | G19: L3: APPLY | I19: L4: ANALYSE | K19: L5: EVALUATE | M19: L6: CREATE | P19: MARK ALLOCATION
B20: S. No | C20: Reg. No. | D20: Name of the Student | E20: IAT-II | F20: Part A | K20: Part B | P20: CO 1 Attainment | R20: CO 2 Attainment | T20: CO 3 Attainment | V20: CO 4 Attainment | X20: CO 5 Attainment | Z20: TOTAL MARK
E21: Q.No. | F21: 1 | G21: 2 | H21: 3 | I21: 4 | J21: 5 | K21: 6 | L21: 7 | M21: 8 | N21: 9 | O21: 10
E23: CO | F23: =IF('BL-2'!C20="ü",1,IF('BL-2'!C21="ü",2,IF('BL-2'!C22="ü",3,IF('BL-2'!C23="ü",4,IF('BL-2'!C24="ü",5,0))))) -> 3 | G23: =IF('BL-2'!D20="ü",1,IF('BL-2'!D21="ü",2,IF('BL-2'!D22="ü",3,IF('BL-2'!D23="ü",4,IF('BL-2'!D24="ü",5,0))))) -> 4 | H23: =IF('BL-2'!E20="ü",1,IF('BL-2'!E21="ü",2,IF('BL-2'!E22="ü",3,IF('BL-2'!E23="ü",4,IF('BL-2'!E24="ü",5,0))))) -> 4 | I23: =IF('BL-2'!F20="ü",1,IF('BL-2'!F21="ü",2,IF('BL-2'!F22="ü",3,IF('BL-2'!F23="ü",4,IF('BL-2'!F24="ü",5,0))))) -> 5 | J23: =IF('BL-2'!G20="ü",1,IF('BL-2'!G21="ü",2,IF('BL-2'!G22="ü",3,IF('BL-2'!G23="ü",4,IF('BL-2'!G24="ü",5,0))))) -> 5 | K23: =IF('BL-2'!H20="ü",1,IF('BL-2'!H21="ü",2,IF('BL-2'!H22="ü",3,IF('BL-2'!H23="ü",4,IF('BL-2'!H24="ü",5,0))))) -> 3 | L23: =IF('BL-2'!I20="ü",1,IF('BL-2'!I21="ü",2,IF('BL-2'!I22="ü",3,IF('BL-2'!I23="ü",4,IF('BL-2'!I24="ü",5,0))))) -> 4 | M23: =IF('BL-2'!J20="ü",1,IF('BL-2'!J21="ü",2,IF('BL-2'!J22="ü",3,IF('BL-2'!J23="ü",4,IF('BL-2'!J24="ü",5,0))))) -> 4 | ... O23: =IF('BL-2'!L20="ü",1,IF('BL-2'!L21="ü",2,IF('BL-2'!L22="ü",3,IF('BL-2'!L23="ü",4,IF('BL-2'!L24="ü",5,0))))) -> 5
E24: BL | F24: =IF('BL-2'!C25="ü","L1",IF('BL-2'!C26="ü","L2",IF('BL-2'!C27="ü","L3",IF('BL-2'!C28="ü","L4",IF('BL-2'!C29="ü","L5","L6"))))) -> L2 | G24: =IF('BL-2'!D25="ü","L1",IF('BL-2'!D26="ü","L2",IF('BL-2'!D27="ü","L3",IF('BL-2'!D28="ü","L4",IF('BL-2'!D29="ü","L5","L6"))))) -> L4 | H24: =IF('BL-2'!E25="ü","L1",IF('BL-2'!E26="ü","L2",IF('BL-2'!E27="ü","L3",IF('BL-2'!E28="ü","L4",IF('BL-2'!E29="ü","L5","L6"))))) -> L1 | I24: =IF('BL-2'!F25="ü","L1",IF('BL-2'!F26="ü","L2",IF('BL-2'!F27="ü","L3",IF('BL-2'!F28="ü","L4",IF('BL-2'!F29="ü","L5","L6"))))) -> L2 | J24: =IF('BL-2'!G25="ü","L1",IF('BL-2'!G26="ü","L2",IF('BL-2'!G27="ü","L3",IF('BL-2'!G28="ü","L4",IF('BL-2'!G29="ü","L5","L6"))))) -> L2 | K24: =IF('BL-2'!H25="ü","L1",IF('BL-2'!H26="ü","L2",IF('BL-2'!H27="ü","L3",IF('BL-2'!H28="ü","L4",IF('BL-2'!H29="ü","L5","L6"))))) -> L2 | L24: =IF('BL-2'!I25="ü","L1",IF('BL-2'!I26="ü","L2",IF('BL-2'!I27="ü","L3",IF('BL-2'!I28="ü","L4",IF('BL-2'!I29="ü","L5","L6"))))) -> L2 | M24: =IF('BL-2'!J25="ü","L1",IF('BL-2'!J26="ü","L2",IF('BL-2'!J27="ü","L3",IF('BL-2'!J28="ü","L4",IF('BL-2'!J29="ü","L5","L6"))))) -> L4 | ... O24: =IF('BL-2'!L25="ü","L1",IF('BL-2'!L26="ü","L2",IF('BL-2'!L27="ü","L3",IF('BL-2'!L28="ü","L4",IF('BL-2'!L29="ü","L5","L6"))))) -> L6
E25: MARK | F25: 2 | G25: 2 | H25: 2 | I25: 2 | J25: 2 | K25: 7 | L25: 7 | M25: 7 | N25: 7 | O25: 12 | P25: =SUMIF('BL-2'!$C$20:$L$20,"*",'IAT-2'!F25:O25) -> 0 | Q25: 100 | R25: =SUMIF('BL-2'!$C$21:$L$21,"*",'IAT-2'!F25:O25) -> 0 | S25: 100 | T25: =SUMIF('BL-2'!$C$22:$L$22,"*",'IAT-2'!F25:O25) -> 9 | U25: 100 | V25: =SUMIF('BL-2'!$C$23:$L$23,"*",'IAT-2'!F25:O25) -> 18 | W25: 100 | X25: =SUMIF('BL-2'!$C$24:$L$24,"*",'IAT-2'!F25:O25) -> 23 | Y25: 100 | Z25: 50 | AA25: =Z25*2 -> 100
B26: 1 | C26: ='IAT-1'!C26 -> 951323243001 | D26: ='IAT-1'!D26 -> ABINAYA S | F26: ='I2'!D15 -> 2 | G26: ='I2'!E15 -> 1 | H26: ='I2'!F15 -> 0 | I26: ='I2'!G15 -> 1 | J26: ='I2'!H15 -> 0 | K26: ='I2'!I15+'I2'!J15 -> 6 | L26: ='I2'!K15+'I2'!L15 -> 5 | M26: ='I2'!M15+'I2'!N15 -> 0 | N26: ='I2'!O15+'I2'!P15 -> 0 | O26: ='I2'!Q15+'I2'!R15 -> 11 | P26: =SUMIF('BL-2'!$C$20:$L$20,"*",'IAT-2'!F26:O26) -> 0 | Q26: =ROUND(IFERROR(P26/P$25,0)*100,1) -> 0 | R26: =SUMIF('BL-2'!$C$21:$L$21,"*",'IAT-2'!F26:O26) -> 0 | S26: =ROUND(IFERROR(R26/R$25,0)*100,1) -> 0 | T26: =SUMIF('BL-2'!$C$22:$L$22,"*",'IAT-2'!F26:O26) -> 8 | U26: =ROUND(IFERROR(T26/T$25,0)*100,1) -> 88.9 | V26: =SUMIF('BL-2'!$C$23:$L$23,"ü",'IAT-2'!F26:O26) -> 6 | W26: =ROUND(IFERROR(V26/V$25,0)*100,1) -> 33.3 | X26: =SUMIF('BL-2'!$C$24:$L$24,"*",'IAT-2'!F26:O26) -> 12 | Y26: =ROUND(IFERROR(X26/X$25,0)*100,1) -> 52.2 | Z26: =SUM(P26,R26,T26,V26,X26) -> 26 | AA26: =Z26*2 -> 52
B27: 2 | C27: ='IAT-1'!C27 -> 951323243002 | D27: ='IAT-1'!D27 -> ABISHEK S | F27: ='I2'!D16 -> 0 | G27: ='I2'!E16 -> 0 | H27: ='I2'!F16 -> 0 | I27: ='I2'!G16 -> 0 | J27: ='I2'!H16 -> 0 | K27: ='I2'!I16+'I2'!J16 -> 0 | L27: ='I2'!K16+'I2'!L16 -> 0 | M27: ='I2'!M16+'I2'!N16 -> 0 | N27: ='I2'!O16+'I2'!P16 -> 0 | O27: ='I2'!Q16+'I2'!R16 -> 0 | P27: =SUMIF('BL-2'!$C$20:$L$20,"*",'IAT-2'!F27:O27) -> 0 | Q27: =ROUND(IFERROR(P27/P$25,0)*100,1) -> 0 | R27: =SUMIF('BL-2'!$C$21:$L$21,"*",'IAT-2'!F27:O27) -> 0 | S27: =ROUND(IFERROR(R27/R$25,0)*100,1) -> 0 | T27: =SUMIF('BL-2'!$C$22:$L$22,"*",'IAT-2'!F27:O27) -> 0 | U27: =ROUND(IFERROR(T27/T$25,0)*100,1) -> 0 | V27: =SUMIF('BL-2'!$C$23:$L$23,"ü",'IAT-2'!F27:O27) -> 0 | W27: =ROUND(IFERROR(V27/V$25,0)*100,1) -> 0 | X27: =SUMIF('BL-2'!$C$24:$L$24,"*",'IAT-2'!F27:O27) -> 0 | Y27: =ROUND(IFERROR(X27/X$25,0)*100,1) -> 0 | Z27: =SUM(P27,R27,T27,V27,X27) -> 0 | AA27: =Z27*2 -> 0
B28: 3 | C28: ='IAT-1'!C28 -> 951323243003 | D28: ='IAT-1'!D28 -> AJEETHA S | F28: ='I2'!D17 -> 0 | G28: ='I2'!E17 -> 0 | H28: ='I2'!F17 -> 0 | I28: ='I2'!G17 -> 0 | J28: ='I2'!H17 -> 0 | K28: ='I2'!I17+'I2'!J17 -> 0 | L28: ='I2'!K17+'I2'!L17 -> 0 | M28: ='I2'!M17+'I2'!N17 -> 0 | N28: ='I2'!O17+'I2'!P17 -> 0 | O28: ='I2'!Q17+'I2'!R17 -> 0 | P28: =SUMIF('BL-2'!$C$20:$L$20,"*",'IAT-2'!F28:O28) -> 0 | Q28: =ROUND(IFERROR(P28/P$25,0)*100,1) -> 0 | R28: =SUMIF('BL-2'!$C$21:$L$21,"*",'IAT-2'!F28:O28) -> 0 | S28: =ROUND(IFERROR(R28/R$25,0)*100,1) -> 0 | T28: =SUMIF('BL-2'!$C$22:$L$22,"*",'IAT-2'!F28:O28) -> 0 | U28: =ROUND(IFERROR(T28/T$25,0)*100,1) -> 0 | V28: =SUMIF('BL-2'!$C$23:$L$23,"ü",'IAT-2'!F28:O28) -> 0 | W28: =ROUND(IFERROR(V28/V$25,0)*100,1) -> 0 | X28: =SUMIF('BL-2'!$C$24:$L$24,"*",'IAT-2'!F28:O28) -> 0 | Y28: =ROUND(IFERROR(X28/X$25,0)*100,1) -> 0 | Z28: =SUM(P28,R28,T28,V28,X28) -> 0 | AA28: =Z28*2 -> 0
B29: 4 | C29: ='IAT-1'!C29 -> 951323243004 | D29: ='IAT-1'!D29 -> AJIM FAYAZ K M S | F29: ='I2'!D18 -> 2 | G29: ='I2'!E18 -> 2 | H29: ='I2'!F18 -> 2 | I29: ='I2'!G18 -> 2 | J29: ='I2'!H18 -> 2 | K29: ='I2'!I18+'I2'!J18 -> 0 | L29: ='I2'!K18+'I2'!L18 -> 0 | M29: ='I2'!M18+'I2'!N18 -> 0 | N29: ='I2'!O18+'I2'!P18 -> 4 | O29: ='I2'!Q18+'I2'!R18 -> 0 | P29: =SUMIF('BL-2'!$C$20:$L$20,"*",'IAT-2'!F29:O29) -> 0 | Q29: =ROUND(IFERROR(P29/P$25,0)*100,1) -> 0 | R29: =SUMIF('BL-2'!$C$21:$L$21,"*",'IAT-2'!F29:O29) -> 0 | S29: =ROUND(IFERROR(R29/R$25,0)*100,1) -> 0 | T29: =SUMIF('BL-2'!$C$22:$L$22,"*",'IAT-2'!F29:O29) -> 2 | U29: =ROUND(IFERROR(T29/T$25,0)*100,1) -> 22.2 | V29: =SUMIF('BL-2'!$C$23:$L$23,"ü",'IAT-2'!F29:O29) -> 4 | W29: =ROUND(IFERROR(V29/V$25,0)*100,1) -> 22.2 | X29: =SUMIF('BL-2'!$C$24:$L$24,"*",'IAT-2'!F29:O29) -> 8 | Y29: =ROUND(IFERROR(X29/X$25,0)*100,1) -> 34.8 | Z29: =SUM(P29,R29,T29,V29,X29) -> 14 | AA29: =Z29*2 -> 28
B30: 5 | C30: ='IAT-1'!C30 -> 951323243005 | D30: ='IAT-1'!D30 -> ALPHONES CRUZ NAVEEN J | F30: ='I2'!D19 -> 1 | G30: ='I2'!E19 -> 2 | H30: ='I2'!F19 -> 2 | I30: ='I2'!G19 -> 2 | J30: ='I2'!H19 -> 1 | K30: ='I2'!I19+'I2'!J19 -> 6 | L30: ='I2'!K19+'I2'!L19 -> 0 | M30: ='I2'!M19+'I2'!N19 -> 0 | N30: ='I2'!O19+'I2'!P19 -> 0 | O30: ='I2'!Q19+'I2'!R19 -> 0 | P30: =SUMIF('BL-2'!$C$20:$L$20,"*",'IAT-2'!F30:O30) -> 0 | Q30: =ROUND(IFERROR(P30/P$25,0)*100,1) -> 0 | R30: =SUMIF('BL-2'!$C$21:$L$21,"*",'IAT-2'!F30:O30) -> 0 | S30: =ROUND(IFERROR(R30/R$25,0)*100,1) -> 0 | T30: =SUMIF('BL-2'!$C$22:$L$22,"*",'IAT-2'!F30:O30) -> 7 | U30: =ROUND(IFERROR(T30/T$25,0)*100,1) -> 77.8 | V30: =SUMIF('BL-2'!$C$23:$L$23,"ü",'IAT-2'!F30:O30) -> 4 | W30: =ROUND(IFERROR(V30/V$25,0)*100,1) -> 22.2 | X30: =SUMIF('BL-2'!$C$24:$L$24,"*",'IAT-2'!F30:O30) -> 3 | Y30: =ROUND(IFERROR(X30/X$25,0)*100,1) -> 13 | Z30: =SUM(P30,R30,T30,V30,X30) -> 14 | AA30: =Z30*2 -> 28
B31: 6 | C31: ='IAT-1'!C31 -> 951323243006 | D31: ='IAT-1'!D31 -> ANGEL AGNES D | F31: ='I2'!D20 -> 2 | G31: ='I2'!E20 -> 1 | H31: ='I2'!F20 -> 2 | I31: ='I2'!G20 -> 2 | J31: ='I2'!H20 -> 1 | K31: ='I2'!I20+'I2'!J20 -> 7 | L31: ='I2'!K20+'I2'!L20 -> 6 | M31: ='I2'!M20+'I2'!N20 -> 5 | N31: ='I2'!O20+'I2'!P20 -> 6 | O31: ='I2'!Q20+'I2'!R20 -> 11 | P31: =SUMIF('BL-2'!$C$20:$L$20,"*",'IAT-2'!F31:O31) -> 0 | Q31: =ROUND(IFERROR(P31/P$25,0)*100,1) -> 0 | R31: =SUMIF('BL-2'!$C$21:$L$21,"*",'IAT-2'!F31:O31) -> 0 | S31: =ROUND(IFERROR(R31/R$25,0)*100,1) -> 0 | T31: =SUMIF('BL-2'!$C$22:$L$22,"*",'IAT-2'!F31:O31) -> 9 | U31: =ROUND(IFERROR(T31/T$25,0)*100,1) -> 100 | V31: =SUMIF('BL-2'!$C$23:$L$23,"ü",'IAT-2'!F31:O31) -> 14 | W31: =ROUND(IFERROR(V31/V$25,0)*100,1) -> 77.8 | X31: =SUMIF('BL-2'!$C$24:$L$24,"*",'IAT-2'!F31:O31) -> 20 | Y31: =ROUND(IFERROR(X31/X$25,0)*100,1) -> 87 | Z31: =SUM(P31,R31,T31,V31,X31) -> 43 | AA31: =Z31*2 -> 86
B32: 7 | C32: ='IAT-1'!C32 -> 951323243007 | D32: ='IAT-1'!D32 -> ANUSHA P | F32: ='I2'!D21 -> 2 | G32: ='I2'!E21 -> 1 | H32: ='I2'!F21 -> 2 | I32: ='I2'!G21 -> 2 | J32: ='I2'!H21 -> 2 | K32: ='I2'!I21+'I2'!J21 -> 7 | L32: ='I2'!K21+'I2'!L21 -> 7 | M32: ='I2'!M21+'I2'!N21 -> 7 | N32: ='I2'!O21+'I2'!P21 -> 7 | O32: ='I2'!Q21+'I2'!R21 -> 12 | P32: =SUMIF('BL-2'!$C$20:$L$20,"*",'IAT-2'!F32:O32) -> 0 | Q32: =ROUND(IFERROR(P32/P$25,0)*100,1) -> 0 | R32: =SUMIF('BL-2'!$C$21:$L$21,"*",'IAT-2'!F32:O32) -> 0 | S32: =ROUND(IFERROR(R32/R$25,0)*100,1) -> 0 | T32: =SUMIF('BL-2'!$C$22:$L$22,"*",'IAT-2'!F32:O32) -> 9 | U32: =ROUND(IFERROR(T32/T$25,0)*100,1) -> 100 | V32: =SUMIF('BL-2'!$C$23:$L$23,"ü",'IAT-2'!F32:O32) -> 17 | W32: =ROUND(IFERROR(V32/V$25,0)*100,1) -> 94.4 | X32: =SUMIF('BL-2'!$C$24:$L$24,"*",'IAT-2'!F32:O32) -> 23 | Y32: =ROUND(IFERROR(X32/X$25,0)*100,1) -> 100 | Z32: =SUM(P32,R32,T32,V32,X32) -> 49 | AA32: =Z32*2 -> 98
B33: 8 | C33: ='IAT-1'!C33 -> 951323243008 | D33: ='IAT-1'!D33 -> ARIBA M | F33: ='I2'!D22 -> 1 | G33: ='I2'!E22 -> 0 | H33: ='I2'!F22 -> 0 | I33: ='I2'!G22 -> 1 | J33: ='I2'!H22 -> 1 | K33: ='I2'!I22+'I2'!J22 -> 5 | L33: ='I2'!K22+'I2'!L22 -> 7 | M33: ='I2'!M22+'I2'!N22 -> 0 | N33: ='I2'!O22+'I2'!P22 -> 7 | O33: ='I2'!Q22+'I2'!R22 -> 12 | P33: =SUMIF('BL-2'!$C$20:$L$20,"*",'IAT-2'!F33:O33) -> 0 | Q33: =ROUND(IFERROR(P33/P$25,0)*100,1) -> 0 | R33: =SUMIF('BL-2'!$C$21:$L$21,"*",'IAT-2'!F33:O33) -> 0 | S33: =ROUND(IFERROR(R33/R$25,0)*100,1) -> 0 | T33: =SUMIF('BL-2'!$C$22:$L$22,"*",'IAT-2'!F33:O33) -> 6 | U33: =ROUND(IFERROR(T33/T$25,0)*100,1) -> 66.7 | V33: =SUMIF('BL-2'!$C$23:$L$23,"ü",'IAT-2'!F33:O33) -> 7 | W33: =ROUND(IFERROR(V33/V$25,0)*100,1) -> 38.9 | X33: =SUMIF('BL-2'!$C$24:$L$24,"*",'IAT-2'!F33:O33) -> 21 | Y33: =ROUND(IFERROR(X33/X$25,0)*100,1) -> 91.3 | Z33: =SUM(P33,R33,T33,V33,X33) -> 34 | AA33: =Z33*2 -> 68
B34: 9 | C34: ='IAT-1'!C34 -> 951323243009 | D34: ='IAT-1'!D34 -> BALADHARSHINI S | F34: ='I2'!D23 -> 1 | G34: ='I2'!E23 -> 1 | H34: ='I2'!F23 -> 2 | I34: ='I2'!G23 -> 2 | J34: ='I2'!H23 -> 1 | K34: ='I2'!I23+'I2'!J23 -> 6 | L34: ='I2'!K23+'I2'!L23 -> 6 | M34: ='I2'!M23+'I2'!N23 -> 6 | N34: ='I2'!O23+'I2'!P23 -> 6 | O34: ='I2'!Q23+'I2'!R23 -> 11 | P34: =SUMIF('BL-2'!$C$20:$L$20,"*",'IAT-2'!F34:O34) -> 0 | Q34: =ROUND(IFERROR(P34/P$25,0)*100,1) -> 0 | R34: =SUMIF('BL-2'!$C$21:$L$21,"*",'IAT-2'!F34:O34) -> 0 | S34: =ROUND(IFERROR(R34/R$25,0)*100,1) -> 0 | T34: =SUMIF('BL-2'!$C$22:$L$22,"*",'IAT-2'!F34:O34) -> 7 | U34: =ROUND(IFERROR(T34/T$25,0)*100,1) -> 77.8 | V34: =SUMIF('BL-2'!$C$23:$L$23,"ü",'IAT-2'!F34:O34) -> 15 | W34: =ROUND(IFERROR(V34/V$25,0)*100,1) -> 83.3 | X34: =SUMIF('BL-2'!$C$24:$L$24,"*",'IAT-2'!F34:O34) -> 20 | Y34: =ROUND(IFERROR(X34/X$25,0)*100,1) -> 87 | Z34: =SUM(P34,R34,T34,V34,X34) -> 42 | AA34: =Z34*2 -> 84
B35: 10 | C35: ='IAT-1'!C35 -> 951323243010 | D35: ='IAT-1'!D35 -> BALASANKAR AYYAPPAN M | F35: ='I2'!D24 -> 2 | G35: ='I2'!E24 -> 2 | H35: ='I2'!F24 -> 1 | I35: ='I2'!G24 -> 2 | J35: ='I2'!H24 -> 2 | K35: ='I2'!I24+'I2'!J24 -> 4 | L35: ='I2'!K24+'I2'!L24 -> 2 | M35: ='I2'!M24+'I2'!N24 -> 6 | N35: ='I2'!O24+'I2'!P24 -> 7 | O35: ='I2'!Q24+'I2'!R24 -> 11 | P35: =SUMIF('BL-2'!$C$20:$L$20,"*",'IAT-2'!F35:O35) -> 0 | Q35: =ROUND(IFERROR(P35/P$25,0)*100,1) -> 0 | R35: =SUMIF('BL-2'!$C$21:$L$21,"*",'IAT-2'!F35:O35) -> 0 | S35: =ROUND(IFERROR(R35/R$25,0)*100,1) -> 0 | T35: =SUMIF('BL-2'!$C$22:$L$22,"*",'IAT-2'!F35:O35) -> 6 | U35: =ROUND(IFERROR(T35/T$25,0)*100,1) -> 66.7 | V35: =SUMIF('BL-2'!$C$23:$L$23,"ü",'IAT-2'!F35:O35) -> 11 | W35: =ROUND(IFERROR(V35/V$25,0)*100,1) -> 61.1 | X35: =SUMIF('BL-2'!$C$24:$L$24,"*",'IAT-2'!F35:O35) -> 22 | Y35: =ROUND(IFERROR(X35/X$25,0)*100,1) -> 95.7 | Z35: =SUM(P35,R35,T35,V35,X35) -> 39 | AA35: =Z35*2 -> 78
B36: 11 | C36: ='IAT-1'!C36 -> 951323243011 | D36: ='IAT-1'!D36 -> BALA SRI RAM G | F36: ='I2'!D25 -> 2 | G36: ='I2'!E25 -> 1 | H36: ='I2'!F25 -> 2 | I36: ='I2'!G25 -> 1 | J36: ='I2'!H25 -> 2 | K36: ='I2'!I25+'I2'!J25 -> 0 | L36: ='I2'!K25+'I2'!L25 -> 0 | M36: ='I2'!M25+'I2'!N25 -> 0 | N36: ='I2'!O25+'I2'!P25 -> 0 | O36: ='I2'!Q25+'I2'!R25 -> 11 | P36: =SUMIF('BL-2'!$C$20:$L$20,"*",'IAT-2'!F36:O36) -> 0 | Q36: =ROUND(IFERROR(P36/P$25,0)*100,1) -> 0 | R36: =SUMIF('BL-2'!$C$21:$L$21,"*",'IAT-2'!F36:O36) -> 0 | S36: =ROUND(IFERROR(R36/R$25,0)*100,1) -> 0 | T36: =SUMIF('BL-2'!$C$22:$L$22,"*",'IAT-2'!F36:O36) -> 2 | U36: =ROUND(IFERROR(T36/T$25,0)*100,1) -> 22.2 | V36: =SUMIF('BL-2'!$C$23:$L$23,"ü",'IAT-2'!F36:O36) -> 3 | W36: =ROUND(IFERROR(V36/V$25,0)*100,1) -> 16.7 | X36: =SUMIF('BL-2'!$C$24:$L$24,"*",'IAT-2'!F36:O36) -> 14 | Y36: =ROUND(IFERROR(X36/X$25,0)*100,1) -> 60.9 | Z36: =SUM(P36,R36,T36,V36,X36) -> 19 | AA36: =Z36*2 -> 38
